Workbook
Name AgentsRequired: OFFSET('[1]Day Planner'!$E$15,1,0,COUNT('[1]Day Planner'!$D$16:$D$63))
Name ESLAgentsAvailable: OFFSET('[1]Expected Service Level'!$E$15,1,0,COUNT('[1]Expected Service Level'!$D$16:$D$47))
Name ESLIncomingCalls: OFFSET('[1]Expected Service Level'!$D$15,1,0,COUNT('[1]Expected Service Level'!$D$16:$D$47))
Name ESLReqAgents: OFFSET('[1]Expected Service Level'!$G$15,1,0,COUNT('[1]Expected Service Level'!$D$16:$D$47))
Name ESLTimeRange: OFFSET('[1]Expected Service Level'!$C$15,1,0,COUNT('[1]Expected Service Level'!$D$16:$D$47))
Name IncomingCalls: OFFSET('[1]Day Planner'!$D$15,1,0,COUNT('[1]Day Planner'!$D$16:$D$63))
Name TimeRange: OFFSET('[1]Day Planner'!$C$15,1,0,COUNT('[1]Day Planner'!$D$16:$D$63))

Sheet S&E
C3: Planning S&E semaine | F3: ="S"&_xlfn.ISOWEEKNUM(H3) -> S20 | G3: du | H3: 46153 | I3: au | J3: =H3+6 -> 46159
C5: BO SUP | D5: =H3 -> 46153 | E5: =D5+1 -> 46154 | F5: =E5+1 -> 46155 | G5: =F5+1 -> 46156 | H5: =G5+1 -> 46157 | I5: =H5+1 -> 46158 | J5: =I5+1 -> 46159
B6: BENUE | C6: ANDRE CALVIN | D6: Off | E6: Off | F6: 07h-16h | G6: 07h-16h | H6: 07h-16h | I6: 13h-22h | J6: 13h-22h
B7: WOURI | C7: MADELEINE N | D7: 09h-18h | E7: 07h-16h | F7: 07h-16h | G7: FERIE | H7: 13h-22h | I7: Off | J7: Off
B8: SANAGA | C8: HERVE B | D8: 13h-22h | E8: 13h-22h | F8: Off | G8: FERIE | H8: Off | I8: 07h-16h | J8: 13h-22h
B9: CHARI | C9: PATRICK A | D9: 07h-16h | E9: 07h-16h | F9: 13h-22h | G9: 13h-22h | H9: NUIT | I9: Off | J9: Off
B10: LOGONE | C10: GEROME B | D10: 13h-22h | E10: NUIT | F10: Off | G10: FERIE | H10: Off | I10: 07h-16h | J10: 07h-16h
B11: KYC/Whatsapp | C11: LYONEL K | D11: 07h-16h | E11: 13h-22h | F11: 13h-22h | G11: FERIE | H11: Off | I11: Off | J11: 07h-16h
B15: WFM et REPORTING | C15: ="GF_"&F3 -> GF_S20 | D15: =D5 -> 46153 | E15: =E5 -> 46154 | F15: =F5 -> 46155 | G15: =G5 -> 46156 | H15: =H5 -> 46157 | I15: =I5 -> 46158 | J15: =J5 -> 46159
C16: ARMELLE | D16: 07h-16h | E16: 07h-16h | F16: 07h-16h | G16: 07h-16h | H16: 07h-16h | I16: OFF | J16: OFF
C17: JEAN DANIEL | D17: 07h-16h | E17: 07h-16h | F17: 07h-16h | G17: FERIE | H17: 07h-16h | I17: OFF | J17: OFF
C18: GISCARD | D18: 07h-16h | E18: 07h-16h | F18: 07h-16h | G18: 07h-16h | H18: 07h-16h | I18: OFF | J18: OFF
C19: DAMARIS | D19: OFF | E19: OFF | F19: 07h-16h | G19: 07h-16h | H19: 07h-16h | I19: 13h-22h | J19: 13h-22h
C20: MARIUS | D20: 07h-16h | E20: 07h-16h | F20: 07h-16h | G20: 13h-22h | H20: 13h-22h | I20: OFF | J20: OFF
C21: LUC | D21: 13h-22h | E21: 13h-22h | F21: OFF | G21: FERIE | H21: OFF | I21: 07h-16h | J21: 07h-16h
C22: JULIENNE | D22: 07h-16h | E22: 07h-16h | F22: 13h-22h | G22: FERIE | H22: 07h-16h | I22: OFF | J22: OFF
B26: MULTI CAMPAGNE | C26: ="BU_VIZION_"&F3 -> BU_VIZION_S20 | D26: =D15 -> 46153 | E26: =E15 -> 46154 | F26: =F15 -> 46155 | G26: =G15 -> 46156 | H26: =H15 -> 46157 | I26: =I15 -> 46158 | J26: =J15 -> 46159
C27: Dave Essama | D27: 07h-16h | E27: 07h-16h | F27: 13h-22h | G27: 07h-16h | H27: 13h-22h | I27: OFF | J27: OFF
C28: Josiane Boyomo | D28: 13h-22h | E28: 13h-22h | F28: OFF | G28: FERIE | H28: OFF | I28: 07h-16h | J28: 07h-16h
C30: Rodrigue Beyeck | D30: 07h-16h | E30: 07h-16h | F30: 07h-16h | G30: FERIE | H30: 07h-16h | I30: OFF | J30: OFF
C33: ="RE_"&F3 -> RE_S20 | D33: =D26 -> 46153 | E33: =E26 -> 46154 | F33: =F26 -> 46155 | G33: =G26 -> 46156 | H33: =H26 -> 46157 | I33: =I26 -> 46158 | J33: =J26 -> 46159
B34: INNOVATION | C34: LUCIE | D34: OFF | E34: OFF | F34: 07h-16h | G34: FERIE | H34: 13h-22h | I34: 13h-22h | J34: 13h-22h
B35: AUDACITY | C35: ALEXANDRA | G35: FERIE | J35: OFF
B36: PROFESSIONALISM | C36: LAKENE | I36: OFF | J36: OFF
B37: DISTRIBUTEURS | C37: HORLINE | D37: 08h-17h | E37: 08h-17h | F37: OFF | G37: 08h-17h | H37: 08h-17h | I37: OFF | J37: 08h-17h
B38: HONESTY | C38: JOSEPH | D38: 13h-22h | E38: 13h-22h | F38: 13h-22h | G38: 13h-22h | H38: OFF | I38: OFF | J38: 07h-16h
B39: INTEGRITY | C39: RAISSA MATHO | D39: 07h-16h | E39: 08h-17h | F39: 08h-17h | G39: 13h-22h | H39: 13h-22h | I39: OFF | J39: OFF
B40: ASSISTANCE | C40: ZOULE | D40: 13h-22h | E40: 13h-22h | F40: OFF | G40: OFF | H40: 07h-16h | I40: 07h-16h | J40: 08h-17h
B41: SEYO | C41: TRESOR | D41: 07h-16h | E41: 07h-16h | F41: 13h-22h | G41: NUIT | H41: OFF | I41: OFF | J41: 07h-16h
B42: NUIT | C42: FADIMATOU | D42: NUIT | E42: OFF | F42: NUIT | G42: FERIE | H42: OFF | I42: NUIT | J42: NUIT
B43: BURAL | C43: NADEGE | D43: 13h-22h | E43: 13h-22h | F43: 13h-22h | G43: OFF | H43: OFF | I43: 07h-16h | J43: 13h-22h
B44: CONNEXION+ | C44: SAMUEL MISSIKA | D44: OFF | E44: 07h-16h | F44: 07h-16h | G44: 07h-16h | H44: 13h-22h | I44: 13h-22h | J44: OFF
B45: PERFORMANCE | C45: BALOGNYE EMMA SANDRINE | D45: 08h-17h | E45: 08h-17h | F45: OFF | G45: FERIE | H45: 08h-17h | I45: 13h-22h | J45: OFF
B46: AMANA | C46: MOISE | D46: CA3 | E46: CA3 | F46: CA3 | G46: CA3 | H46: CA3 | I46: CA3 | J46: CA3
B52: DA | C52: AUDREY L | D52: 07h-16h | E52: 07h-16h | F52: 13h-22h | G52: FERIE | H52: 13h-22h | I52: OFF | J52: OFF
C53: PATRICK G | D53: CA1 | E53: CA1 | F53: CA1 | G53: CA1 | H53: CA1 | I53: CA1 | J53: CA1
C54: DIANE | D54: 13h-22h | E54: OFF | F54: OFF | G54: 07h-16h | H54: 07h-16h | I54: 13h-22h | J54: 16h-22h
B56: RP | C56: SIMON | D56: 07h-16h | E56: 07h-16h | F56: 07h-16h | G56: FERIE | H56: 07h-16h | I56: OFF | J56: OFF
C57: PIERRETTE | D57: 07h-16h | E57: 07h-16h | F57: 07h-16h | G57: FERIE | H57: 07h-16h | I57: OFF | J57: OFF
B59: EM | C59: ="EM_"&F3 -> EM_S20 | D59: =D33 -> 46153 | E59: =E33 -> 46154 | F59: =F33 -> 46155 | G59: =G33 -> 46156 | H59: =H33 -> 46157 | I59: =I33 -> 46158 | J59: =J33 -> 46159
...

Sheet At_Réu
C3: REUNION D'EQUIPE /ATELIERS
C6: REUNION D'EQUIPE & ATELIER | D6: tranches | E6: ='S&E'!H3 -> 46153 | F6: =E6+1 -> 46154 | G6: =F6+1 -> 46155 | H6: =G6+1 -> 46156 | I6: =H6+1 -> 46157 | J6: =I6+1 -> 46158 | K6: =J6+1 -> 46159
D7: 07h30-09h

Sheet AE
B1: ="S"&_xlfn.ISOWEEKNUM(F1) -> S19 | F1: 46146 | K1: =F1+1 -> 46147 | P1: =K1+1 -> 46148 | U1: =P1+1 -> 46149 | Z1: =U1+1 -> 46150 | AE1: =Z1+1 -> 46151 | AJ1: =AE1+1 -> 46152 | AO1: 1.6666667 | AP1: =AO2/AO1 -> 135.9875 | AR1: =SUM(AR14:AR158) -> 0 | AS1: =SUM(AS14:AS48) -> 0 | BT1: :
F2: Total jour | G2: =J2/"8:00:00" -> 110.5 | H2: =J2/$AO$2 -> 0.16251494 | I2: =COUNT(F4:F158) -> 129 | J2: =SUM(J4:J158) -> 36.833333 | K2: Total jour | L2: =O2/"8:00:00" -> 101 | M2: =O2/$AO$2 -> 0.14854306 | N2: =COUNT(K4:K158) -> 122 | O2: =SUM(O4:O158) -> 33.666667 | P2: Total jour | Q2: =T2/"8:00:00" -> 107 | R2: =T2/$AO$2 -> 0.15736741 | S2: =COUNT(P4:P158) -> 124 | T2: =SUM(T4:T158) -> 35.666667 | U2: Total jour | V2: =Y2/"8:00:00" -> 93.3125 | W2: =Y2/$AO$2 -> 0.13723688 | X2: =COUNT(U4:U158) -> 109 | Y2: =SUM(Y4:Y158) -> 31.104167 | Z2: Total jour | AA2: =AD2/"8:00:00" -> 95 | AB2: =AD2/$AO$2 -> 0.13971872 | AC2: =COUNT(Z4:Z158) -> 111 | AD2: =SUM(AD4:AD158) -> 31.666667 | AE2: Total jour | AF2: =AI2/"8:00:00" -> 91.5 | AG2: =AI2/$AO$2 -> 0.13457119 | AH2: =COUNT(AE4:AE158) -> 95 | AI2: =SUM(AI4:AI158) -> 30.5 | AJ2: Total jour | AK2: =AN2/"8:00:00" -> 81.625 | AL2: =AN2/$AO$2 -> 0.1200478 | AM2: =COUNT(AJ4:AJ158) -> 83 | AN2: =SUM(AN4:AN158) -> 27.208333 | AO2: =SUM(AO4:AO158) -> 226.64583 | AP2: formation/réunion équipe | AQ2: HSUP | AR2: 596 | AT2: 0.33333333 | AW2: 1.6666667
B3: Agents | C3: comm1 | D3: TEAM | E3: Compétences | F3: Début | G3: Pause | I3: Fin | J3: Total | K3: Début | L3: Pause | N3: Fin | O3: Total | P3: Début | Q3: Pause | S3: Fin | T3: Total | U3: Début | V3: Pause | X3: Fin | Y3: Total | Z3: Début | AA3: Pause | AC3: Fin | AD3: Total | AE3: Début | AF3: Pause | AH3: Fin | AI3: Total | AJ3: Début | AK3: Pause | AM3: Fin | AN3: Total | AO3: Total | AP3: formation/réunion équipe | AR3: gestion des coûts | AS3: dépassement
B4: NDEНТСНЕK SAKOANE ELISABETH | D4: AMANA | E4: FFD | F4: OFF | G4: OFF | H4: OFF | I4: OFF | J4: =IFERROR(MOD(I4-F4,1)-MOD(H4-G4,1),"") | K4: OFF | L4: OFF | M4: OFF | N4: OFF | O4: =IFERROR(MOD(N4-K4,1)-MOD(M4-L4,1),"") | P4: 0.5 | Q4: 0.72916667 | R4: 0.77083333 | S4: 0.91666667 | T4: =IFERROR(MOD(S4-P4,1)-MOD(R4-Q4,1),"") -> 0.375 | U4: 0.45833333 | V4: 0.625 | W4: 0.66666667 | X4: 0.875 | Y4: =IFERROR(MOD(X4-U4,1)-MOD(W4-V4,1),"") -> 0.375 | Z4: 0.5 | AA4: 0.72916667 | AB4: 0.77083333 | AC4: 0.875 | AD4: =IFERROR(MOD(AC4-Z4,1)-MOD(AB4-AA4,1),"") -> 0.33333333 | AE4: 0.29166667 | AF4: 0.54166667 | AG4: 0.625 | AH4: 0.70833333 | AI4: =IFERROR(MOD(AH4-AE4,1)-MOD(AG4-AF4,1),"") -> 0.33333333 | AJ4: 0.29166667 | AK4: 0.54166667 | AL4: 0.625 | AM4: 0.70833333 | AN4: =IFERROR(MOD(AM4-AJ4,1)-MOD(AL4-AK4,1),"") -> 0.33333333 | AO4: =SUM(J4,O4,T4,Y4,AD4,AI4,AN4) -> 1.75
B5: ABDOUR RAHIM SAMBO | D5: AMANA | E5: FFD | F5: OFF | G5: OFF | H5: OFF | I5: OFF | J5: =IFERROR(MOD(I5-F5,1)-MOD(H5-G5,1),"") | K5: OFF | L5: OFF | M5: OFF | N5: OFF | O5: =IFERROR(MOD(N5-K5,1)-MOD(M5-L5,1),"") | P5: 0.29166667 | Q5: 0.54166667 | R5: 0.625 | S5: 0.70833333 | T5: =IFERROR(MOD(S5-P5,1)-MOD(R5-Q5,1),"") -> 0.33333333 | U5: 0.52083333 | V5: 0.75 | W5: 0.79166667 | X5: 0.9375 | Y5: =IFERROR(MOD(X5-U5,1)-MOD(W5-V5,1),"") -> 0.375 | Z5: 0.54166667 | AA5: 0.75 | AB5: 0.79166667 | AC5: 0.9375 | AD5: =IFERROR(MOD(AC5-Z5,1)-MOD(AB5-AA5,1),"") -> 0.35416667 | AE5: 0.83333333 | AH5: 1 | AI5: =IFERROR(MOD(AH5-AE5,1)-MOD(AG5-AF5,1),"") -> 0.16666667 | AJ5: 0 | AK5: 0.29166667 | AL5: 0.83333333 | AM5: 1 | AN5: 0.375 | AO5: =SUM(J5,O5,T5,Y5,AD5,AI5,AN5) -> 1.6041667
A6: messa | B6: AMINATOU HAMADOU | D6: AMANA | E6: FFD | F6: 0.41666667 | G6: 0.66666667 | H6: 0.75 | I6: 0.83333333 | J6: =IFERROR(MOD(I6-F6,1)-MOD(H6-G6,1),"") -> 0.33333333 | K6: 0.33333333 | L6: 14; | M6: 15; | N6: 0.66666667 | O6: =IFERROR(MOD(N6-K6,1)-MOD(M6-L6,1),"") | P6: 0.5 | Q6: 0.625 | R6: 0.66666667 | S6: 0.875 | T6: =IFERROR(MOD(S6-P6,1)-MOD(R6-Q6,1),"") -> 0.33333333 | U6: OFF | V6: OFF | W6: OFF | X6: OFF | Y6: =IFERROR(MOD(X6-U6,1)-MOD(W6-V6,1),"") | Z6: OFF | AA6: OFF | AB6: OFF | AC6: OFF | AD6: =IFERROR(MOD(AC6-Z6,1)-MOD(AB6-AA6,1),"") | AE6: 0.29166667 | AF6: 0.54166667 | AG6: 0.625 | AH6: 0.70833333 | AI6: =IFERROR(MOD(AH6-AE6,1)-MOD(AG6-AF6,1),"") -> 0.33333333 | AJ6: 0.29166667 | AK6: 0.54166667 | AL6: 0.625 | AM6: 0.70833333 | AN6: =IFERROR(MOD(AM6-AJ6,1)-MOD(AL6-AK6,1),"") -> 0.33333333 | AO6: =SUM(J6,O6,T6,Y6,AD6,AI6,AN6) -> 1.3333333
B7: YAYA BARKINDO | D7: AMANA | E7: FFD | F7: 0.52083333 | G7: 0.75 | H7: 0.79166667 | I7: 0.9375 | J7: =IFERROR(MOD(I7-F7,1)-MOD(H7-G7,1),"") -> 0.375 | K7: 0.52083333 | L7: 0.75 | M7: 0.79166667 | N7: 0.9375 | O7: =IFERROR(MOD(N7-K7,1)-MOD(M7-L7,1),"") -> 0.375 | P7: 0.52083333 | Q7: 0.75 | R7: 0.79166667 | S7: 0.9375 | T7: =IFERROR(MOD(S7-P7,1)-MOD(R7-Q7,1),"") -> 0.375 | U7: OFF | V7: OFF | W7: OFF | X7: OFF | Y7: =IFERROR(MOD(X7-U7,1)-MOD(W7-V7,1),"") | Z7: OFF | AA7: OFF | AB7: OFF | AC7: OFF | AD7: =IFERROR(MOD(AC7-Z7,1)-MOD(AB7-AA7,1),"") | AE7: 0.33333333 | AF7: 0.58333333 | AG7: 0.66666667 | AH7: 0.75 | AI7: =IFERROR(MOD(AH7-AE7,1)-MOD(AG7-AF7,1),"") -> 0.33333333 | AJ7: 0.45833333 | AK7: 0.64583333 | AL7: 0.72916667 | AM7: 0.875 | AN7: =IFERROR(MOD(AM7-AJ7,1)-MOD(AL7-AK7,1),"") -> 0.33333333 | AO7: =SUM(J7,O7,T7,Y7,AD7,AI7,AN7) -> 1.7916667
A8: ETUDI | B8: KOULTCHOUMI FADIMATOU HAMAN | C8: 6 | D8: AMANA | E8: FFD | F8: 0.66666667 | I8: 0.9375 | J8: =IFERROR(MOD(I8-F8,1)-MOD(H8-G8,1),"") -> 0.27083333 | K8: 0.66666667 | N8: 0.9375 | O8: =IFERROR(MOD(N8-K8,1)-MOD(M8-L8,1),"") -> 0.27083333 | P8: 0.66666667 | S8: 0.9375 | T8: =IFERROR(MOD(S8-P8,1)-MOD(R8-Q8,1),"") -> 0.27083333 | U8: OFF | V8: OFF | W8: OFF | X8: OFF | Y8: =IFERROR(MOD(X8-U8,1)-MOD(W8-V8,1),"") | Z8: OFF | AA8: OFF | AB8: OFF | AC8: OFF | AD8: =IFERROR(MOD(AC8-Z8,1)-MOD(AB8-AA8,1),"") | AE8: 0.29166667 | AH8: 0.5625 | AI8: =IFERROR(MOD(AH8-AE8,1)-MOD(AG8-AF8,1),"") -> 0.27083333 | AJ8: 0.29166667 | AM8: 0.5625 | AN8: =IFERROR(MOD(AM8-AJ8,1)-MOD(AL8-AK8,1),"") -> 0.27083333 | AO8: =SUM(J8,O8,T8,Y8,AD8,AI8,AN8) -> 1.3541667
A9: SIMBO | B9: SAMIRA MOUSSA KONATE | D9: AMANA | E9: FFD | F9: OFF | G9: OFF | H9: OFF | I9: OFF | J9: =IFERROR(MOD(I9-F9,1)-MOD(H9-G9,1),"") | K9: 0.45833333 | L9: 0.70833333 | M9: 0.75 | N9: 0.875 | O9: =IFERROR(MOD(N9-K9,1)-MOD(M9-L9,1),"") -> 0.375 | P9: 0.35416667 | Q9: 0.58333333 | R9: 0.66666667 | S9: 0.77083333 | T9: =IFERROR(MOD(S9-P9,1)-MOD(R9-Q9,1),"") -> 0.33333333 | U9: 0.52083333 | V9: 0.70833333 | W9: 0.75 | X9: 0.9375 | Y9: =IFERROR(MOD(X9-U9,1)-MOD(W9-V9,1),"") -> 0.375 | Z9: 0.52083333 | AA9: 0.72916667 | AB9: 0.77083333 | AC9: 0.9375 | AD9: =IFERROR(MOD(AC9-Z9,1)-MOD(AB9-AA9,1),"") -> 0.375 | AE9: OFF | AF9: OFF | AG9: OFF | AH9: OFF | AI9: =IFERROR(MOD(AH9-AE9,1)-MOD(AG9-AF9,1),"") | AJ9: 0.33333333 | AK9: 0.58333333 | AL9: 0.66666667 | AM9: 0.75 | AN9: =IFERROR(MOD(AM9-AJ9,1)-MOD(AL9-AK9,1),"") -> 0.33333333 | AO9: =SUM(J9,O9,T9,Y9,AD9,AI9,AN9) -> 1.7916667
A10: PALAI | B10: AMINATOU BABA MARLYSE | D10: AMANA | E10: FFD | F10: 0.45833333 | G10: 0.6875 | H10: 0.77083333 | I10: 0.875 | J10: =IFERROR(MOD(I10-F10,1)-MOD(H10-G10,1),"") -> 0.33333333 | K10: 0.5 | L10: 0.75 | M10: 0.79166667 | N10: 0.91666667 | O10: =IFERROR(MOD(N10-K10,1)-MOD(M10-L10,1),"") -> 0.375 | P10: 0.54166667 | Q10: 0.75 | R10: 0.79166667 | S10: 0.9375 | T10: =IFERROR(MOD(S10-P10,1)-MOD(R10-Q10,1),"") -> 0.35416667 | U10: OFF | V10: OFF | W10: OFF | X10: OFF | Y10: =IFERROR(MOD(X10-U10,1)-MOD(W10-V10,1),"") | Z10: OFF | AA10: OFF | AB10: OFF | AC10: OFF | AD10: =IFERROR(MOD(AC10-Z10,1)-MOD(AB10-AA10,1),"") | AE10: 0.29166667 | AF10: 0.5 | AG10: 0.54166667 | AH10: 0.66666667 | AI10: =IFERROR(MOD(AH10-AE10,1)-MOD(AG10-AF10,1),"") -> 0.33333333 | AJ10: 0.29166667 | AK10: 0.5 | AL10: 0.54166667 | AM10: 0.66666667 | AN10: =IFERROR(MOD(AM10-AJ10,1)-MOD(AL10-AK10,1),"") -> 0.33333333 | AO10: =SUM(J10,O10,T10,Y10,AD10,AI10,AN10) -> 1.7291667
A11: MENDO | B11: ZOURMBA JAMES | D11: AMANA | E11: FFD | F11: OFF | G11: OFF | H11: OFF | I11: OFF | J11: =IFERROR(MOD(I11-F11,1)-MOD(H11-G11,1),"") | K11: 0.6875 | N11: 0.9375 | O11: =IFERROR(MOD(N11-K11,1)-MOD(M11-L11,1),"") -> 0.25 | P11: 0.52083333 | Q11: 0.6875 | R11: 0.75 | S11: 0.9375 | T11: =IFERROR(MOD(S11-P11,1)-MOD(R11-Q11,1),"") -> 0.35416667 | U11: 0.66666667 | X11: 0.9375 | Y11: =IFERROR(MOD(X11-U11,1)-MOD(W11-V11,1),"") -> 0.27083333 | Z11: 0.66666667 | AC11: 0.9375 | AD11: =IFERROR(MOD(AC11-Z11,1)-MOD(AB11-AA11,1),"") -> 0.27083333 | AE11: 0.54166667 | AF11: 0.70833333 | AG11: 0.75 | AH11: 0.9375 | AI11: =IFERROR(MOD(AH11-AE11,1)-MOD(AG11-AF11,1),"") -> 0.35416667 | AJ11: OFF | AK11: OFF | AL11: OFF | AM11: OFF | AN11: =IFERROR(MOD(AM11-AJ11,1)-MOD(AL11-AK11,1),"") | AO11: =SUM(J11,O11,T11,Y11,AD11,AI11,AN11) -> 1.5
A12: BRIQU | B12: BAGUIROU | C12: 6 | D12: AMANA | E12: FFD | F12: 0.6875 | I12: 0.9375 | J12: =IFERROR(MOD(I12-F12,1)-MOD(H12-G12,1),"") -> 0.25 | K12: 0.6875 | N12: 0.9375 | O12: =IFERROR(MOD(N12-K12,1)-MOD(M12-L12,1),"") -> 0.25 | P12: OFF | Q12: OFF | R12: OFF | S12: OFF | T12: =IFERROR(MOD(S12-P12,1)-MOD(R12-Q12,1),"") | U12: 0.6875 | X12: 0.9375 | Y12: =IFERROR(MOD(X12-U12,1)-MOD(W12-V12,1),"") -> 0.25 | Z12: 0.6875 | AC12: 0.9375 | AD12: =IFERROR(MOD(AC12-Z12,1)-MOD(AB12-AA12,1),"") -> 0.25 | AE12: 0.6875 | AH12: 0.9375 | AI12: =IFERROR(MOD(AH12-AE12,1)-MOD(AG12-AF12,1),"") -> 0.25 | AJ12: OFF | AK12: OFF | AL12: OFF | AM12: OFF | AN12: =IFERROR(MOD(AM12-AJ12,1)-MOD(AL12-AK12,1),"") | AO12: =SUM(J12,O12,T12,Y12,AD12,AI12,AN12) -> 1.25
A13: ETUDI | B13: BEN NIRYENE TONDJI FRANK LEPERS | C13: 6 | D13: AMANA | E13: FFD | F13: 0.6875 | I13: 0.9375 | J13: =IFERROR(MOD(I13-F13,1)-MOD(H13-G13,1),"") -> 0.25 | K13: 0.6875 | N13: 0.9375 | O13: =IFERROR(MOD(N13-K13,1)-MOD(M13-L13,1),"") -> 0.25 | P13: 0.6875 | S13: 0.9375 | T13: =IFERROR(MOD(S13-P13,1)-MOD(R13-Q13,1),"") -> 0.25 | U13: 0.6875 | X13: 0.9375 | Y13: =IFERROR(MOD(X13-U13,1)-MOD(W13-V13,1),"") -> 0.25 | Z13: 0.83333333 | AC13: 1 | AD13: =IFERROR(MOD(AC13-Z13,1)-MOD(AB13-AA13,1),"") -> 0.16666667 | AE13: 0 | AF13: 0.125 | AG13: 0.20833333 | AH13: 0.29166667 | AI13: =IFERROR(MOD(AH13-AE13,1)-MOD(AG13-AF13,1),"") -> 0.20833333 | AJ13: OFF | AK13: OFF | AL13: OFF | AM13: OFF | AN13: =IFERROR(MOD(AM13-AJ13,1)-MOD(AL13-AK13,1),"") | AO13: =SUM(J13,O13,T13,Y13,AD13,AI13,AN13) -> 1.375
A14: FOUGE | B14: BIN YAMINE AMADOU BOUBA | C14: 6 | D14: AMANA | E14: FFD | F14: 0.83333333 | I14: 1 | J14: =IFERROR(MOD(I14-F14,1)-MOD(H14-G14,1),"") -> 0.16666667 | K14: 0 | L14: 0.125 | M14: 0.20833333 | N14: 0.29166667 | O14: =IFERROR(MOD(N14-K14,1)-MOD(M14-L14,1),"") -> 0.20833333 | P14: OFF | Q14: OFF | R14: OFF | S14: OFF | T14: =IFERROR(MOD(S14-P14,1)-MOD(R14-Q14,1),"") | U14: 0.6875 | X14: 0.9375 | Y14: =IFERROR(MOD(X14-U14,1)-MOD(W14-V14,1),"") -> 0.25 | Z14: 0.6875 | AC14: 0.9375 | AD14: =IFERROR(MOD(AC14-Z14,1)-MOD(AB14-AA14,1),"") -> 0.25 | AE14: 0.6875 | AH14: 0.9375 | AI14: =IFERROR(MOD(AH14-AE14,1)-MOD(AG14-AF14,1),"") -> 0.25 | AJ14: 0.6875 | AM14: 0.9375 | AN14: =IFERROR(MOD(AM14-AJ14,1)-MOD(AL14-AK14,1),"") -> 0.25 | AO14: =SUM(J14,O14,T14,Y14,AD14,AI14,AN14) -> 1.375
A15: ELEVE | B15: DJAGARA MARKOUS | C15: 6 | D15: AMANA | E15: FFD | F15: 0.6875 | I15: 0.9375 | J15: =IFERROR(MOD(I15-F15,1)-MOD(H15-G15,1),"") -> 0.25 | K15: 0.91666667 | N15: 1 | O15: =IFERROR(MOD(N15-K15,1)-MOD(M15-L15,1),"") -> 0.083333333 | P15: 0 | Q15: 0.041666667 | R15: 0.125 | S15: 0.29166667 | T15: =IFERROR(MOD(S15-P15,1)-MOD(R15-Q15,1),"") -> 0.20833333 | U15: OFF | V15: OFF | W15: OFF | X15: OFF | Y15: =IFERROR(MOD(X15-U15,1)-MOD(W15-V15,1),"") | Z15: 0.6875 | AC15: 0.9375 | AD15: =IFERROR(MOD(AC15-Z15,1)-MOD(AB15-AA15,1),"") -> 0.25 | AE15: 0.6875 | AH15: 0.9375 | AI15: =IFERROR(MOD(AH15-AE15,1)-MOD(AG15-AF15,1),"") -> 0.25 | AJ15: 0.6875 | AM15: 0.9375 | AN15: =IFERROR(MOD(AM15-AJ15,1)-MOD(AL15-AK15,1),"") -> 0.25 | AO15: =SUM(J15,O15,T15,Y15,AD15,AI15,AN15) -> 1.2916667
A16: BITEN | B16: MOHAMAN BELLO HAMIDA | D16: AMANA | E16: FFD | F16: OFF | G16: OFF | H16: OFF | I16: OFF | J16: =IFERROR(MOD(I16-F16,1)-MOD(H16-G16,1),"") | K16: 0.29166667 | L16: 0.54166667 | M16: 0.58333333 | N16: 0.70833333 | O16: =IFERROR(MOD(N16-K16,1)-MOD(M16-L16,1),"") -> 0.375 | P16: 0.3125 | Q16: 0.54166667 | R16: 0.625 | S16: 0.72916667 | T16: =IFERROR(MOD(S16-P16,1)-MOD(R16-Q16,1),"") -> 0.33333333 | U16: OFF | V16: OFF | W16: OFF | X16: OFF | Y16: =IFERROR(MOD(X16-U16,1)-MOD(W16-V16,1),"") | Z16: 0.29166667 | AA16: 0.54166667 | AB16: 0.625 | AC16: 0.70833333 | AD16: =IFERROR(MOD(AC16-Z16,1)-MOD(AB16-AA16,1),"") -> 0.33333333 | AE16: 0.54166667 | AF16: 0.70833333 | AG16: 0.75 | AH16: 0.9375 | AI16: =IFERROR(MOD(AH16-AE16,1)-MOD(AG16-AF16,1),"") -> 0.35416667 | AJ16: 0.54166667 | AK16: 0.70833333 | AL16: 0.75 | AM16: 0.9375 | AN16: =IFERROR(MOD(AM16-AJ16,1)-MOD(AL16-AK16,1),"") -> 0.35416667 | AO16: =SUM(J16,O16,T16,Y16,AD16,AI16,AN16) -> 1.75
B17: MESSI MESSI KEVIN TANGUY | D17: ASSISTANCE | E17: FRE | F17: 0.83333333 | I17: 1 | J17: =IFERROR(MOD(I17-F17,1)-MOD(H17-G17,1),"") -> 0.16666667 | K17: 0 | L17: 0.29166667 | M17: 0.83333333 | N17: 1 | O17: 0.375 | P17: 0 | Q17: 0.125 | R17: 0.20833333 | S17: 0.29166667 | T17: =IFERROR(MOD(S17-P17,1)-MOD(R17-Q17,1),"") -> 0.20833333 | U17: OFF | V17: OFF | W17: OFF | X17: OFF | Y17: =IFERROR(MOD(X17-U17,1)-MOD(W17-V17,1),"") | Z17: 0.27083333 | AA17: 0.41666667 | AB17: 0.5 | AC17: 0.6875 | AD17: =IFERROR(MOD(AC17-Z17,1)-MOD(AB17-AA17,1),"") -> 0.33333333 | AE17: 0.5625 | AF17: 0.66666667 | AG17: 0.70833333 | AH17: 0.9375 | AI17: =IFERROR(MOD(AH17-AE17,1)-MOD(AG17-AF17,1),"") -> 0.33333333 | AJ17: 0.5625 | AK17: 0.75 | AL17: 0.79166667 | AM17: 0.9375 | AN17: =IFERROR(MOD(AM17-AJ17,1)-MOD(AL17-AK17,1),"") -> 0.33333333 | AO17: =SUM(J17,O17,T17,Y17,AD17,AI17,AN17) -> 1.75
B18: ALOCK A KIKI LYDIE GAELLE | D18: ASSISTANCE | E18: FRE | F18: 0.41666667 | G18: 0.58333333 | H18: 0.66666667 | I18: 0.83333333 | J18: =IFERROR(MOD(I18-F18,1)-MOD(H18-G18,1),"") -> 0.33333333 | K18: 0.54166667 | L18: 0.75 | M18: 0.79166667 | N18: 0.9375 | O18: =IFERROR(MOD(N18-K18,1)-MOD(M18-L18,1),"") -> 0.35416667 | P18: 0.54166667 | Q18: 0.79166667 | R18: 0.83333333 | S18: 0.9375 | T18: =IFERROR(MOD(S18-P18,1)-MOD(R18-Q18,1),"") -> 0.35416667 | U18: OFF | V18: OFF | W18: OFF | X18: OFF | Y18: =IFERROR(MOD(X18-U18,1)-MOD(W18-V18,1),"") | Z18: OFF | AA18: OFF | AB18: OFF | AC18: OFF | AD18: =IFERROR(MOD(AC18-Z18,1)-MOD(AB18-AA18,1),"") | AE18: 0.29166667 | AF18: 0.54166667 | AG18: 0.625 | AH18: 0.70833333 | AI18: =IFERROR(MOD(AH18-AE18,1)-MOD(AG18-AF18,1),"") -> 0.33333333 | AJ18: 0.29166667 | AK18: 0.54166667 | AL18: 0.625 | AM18: 0.70833333 | AN18: =IFERROR(MOD(AM18-AJ18,1)-MOD(AL18-AK18,1),"") -> 0.33333333 | AO18: =SUM(J18,O18,T18,Y18,AD18,AI18,AN18) -> 1.7083333
B19: MINKOE MENYE IRENE BIBICHE | D19: ASSISTANCE | E19: FRE | F19: 0.41666667 | G19: 0.58333333 | H19: 0.66666667 | I19: 0.83333333 | J19: =IFERROR(MOD(I19-F19,1)-MOD(H19-G19,1),"") -> 0.33333333 | K19: OFF | L19: OFF | M19: OFF | N19: OFF | O19: =IFERROR(MOD(N19-K19,1)-MOD(M19-L19,1),"") | P19: OFF | Q19: OFF | R19: OFF | S19: OFF | T19: =IFERROR(MOD(S19-P19,1)-MOD(R19-Q19,1),"") | U19: 0.45833333 | V19: 0.625 | W19: 0.66666667 | X19: 0.83333333 | Y19: =IFERROR(MOD(X19-U19,1)-MOD(W19-V19,1),"") -> 0.33333333 | Z19: 0.29166667 | AA19: 0.54166667 | AB19: 0.625 | AC19: 0.70833333 | AD19: =IFERROR(MOD(AC19-Z19,1)-MOD(AB19-AA19,1),"") -> 0.33333333 | AE19: 0.54166667 | AF19: 0.66666667 | AG19: 0.70833333 | AH19: 0.9375 | AI19: =IFERROR(MOD(AH19-AE19,1)-MOD(AG19-AF19,1),"") -> 0.35416667 | AJ19: 0.41666667 | AK19: 0.625 | AL19: 0.70833333 | AM19: 0.83333333 | AN19: =IFERROR(MOD(AM19-AJ19,1)-MOD(AL19-AK19,1),"") -> 0.33333333 | AO19: =SUM(J19,O19,T19,Y19,AD19,AI19,AN19) -> 1.6875
A20: NKOLF | B20: SADOU FRÉDÉRIC | D20: ASSISTANCE | E20: FRE | F20: 0.5 | G20: 0.625 | H20: 0.66666667 | I20: 0.875 | J20: =IFERROR(MOD(I20-F20,1)-MOD(H20-G20,1),"") -> 0.33333333 | K20: 0.83333333 | N20: 1 | O20: =IFERROR(MOD(N20-K20,1)-MOD(M20-L20,1),"") -> 0.16666667 | P20: 0 | Q20: 0.29166667 | R20: 0.83333333 | S20: 1 | T20: 0.375 | U20: 0 | V20: 0.16666667 | W20: 0.25 | X20: 0.29166667 | Y20: =IFERROR(MOD(X20-U20,1)-MOD(W20-V20,1),"") -> 0.20833333 | Z20: OFF | AA20: OFF | AB20: OFF | AC20: OFF | AD20: =IFERROR(MOD(AC20-Z20,1)-MOD(AB20-AA20,1),"") | AE20: 0.25 | AF20: 0.5 | AG20: 0.58333333 | AH20: 0.66666667 | AI20: =IFERROR(MOD(AH20-AE20,1)-MOD(AG20-AF20,1),"") -> 0.33333333 | AJ20: 0.54166667 | AK20: 0.70833333 | AL20: 0.75 | AM20: 0.9375 | AN20: =IFERROR(MOD(AM20-AJ20,1)-MOD(AL20-AK20,1),"") -> 0.35416667 | AO20: =SUM(J20,O20,T20,Y20,AD20,AI20,AN20) -> 1.7708333
A21: FEBE | B21: KAMRO MARLENE DIANE | D21: ASSISTANCE | E21: FRE | F21: 0.33333333 | G21: 0.54166667 | H21: 0.54166667 | I21: 0.66666667 | J21: =IFERROR(MOD(I21-F21,1)-MOD(H21-G21,1),"") -> 0.33333333 | K21: 0.39583333 | L21: 0.58333333 | M21: 0.66666667 | N21: 0.8125 | O21: =IFERROR(MOD(N21-K21,1)-MOD(M21-L21,1),"") -> 0.33333333 | P21: 0.41666667 | Q21: 0.66666667 | R21: 0.75 | S21: 0.83333333 | T21: =IFERROR(MOD(S21-P21,1)-MOD(R21-Q21,1),"") -> 0.33333333 | U21: 0.5 | V21: 0.66666667 | W21: 0.70833333 | X21: 0.875 | Y21: =IFERROR(MOD(X21-U21,1)-MOD(W21-V21,1),"") -> 0.33333333 | Z21: 0.54166667 | AA21: 0.75 | AB21: 0.79166667 | AC21: 0.9375 | AD21: =IFERROR(MOD(AC21-Z21,1)-MOD(AB21-AA21,1),"") -> 0.35416667 | AE21: OFF | AF21: OFF | AG21: OFF | AH21: OFF | AI21: =IFERROR(MOD(AH21-AE21,1)-MOD(AG21-AF21,1),"") | AJ21: OFF | AK21: OFF | AL21: OFF | AM21: OFF | AN21: =IFERROR(MOD(AM21-AJ21,1)-MOD(AL21-AK21,1),"") | AO21: =SUM(J21,O21,T21,Y21,AD21,AI21,AN21) -> 1.6875
A22: NKOMK | B22: SI NKOAARNOLD CEDRIC | D22: ASSISTANCE | E22: FRE | F22: 0.27083333 | G22: 0.41666667 | H22: 0.5 | I22: 0.6875 | J22: =IFERROR(MOD(I22-F22,1)-MOD(H22-G22,1),"") -> 0.33333333 | K22: 0.375 | L22: 0.625 | M22: 0.70833333 | N22: 0.79166667 | O22: =IFERROR(MOD(N22-K22,1)-MOD(M22-L22,1),"") -> 0.33333333 | P22: 0.25 | Q22: 0.41666667 | R22: 0.5 | S22: 0.66666667 | T22: =IFERROR(MOD(S22-P22,1)-MOD(R22-Q22,1),"") -> 0.33333333 | U22: 0.83333333 | X22: 1 | Y22: =IFERROR(MOD(X22-U22,1)-MOD(W22-V22,1),"") -> 0.16666667 | Z22: 0 | AA22: 0.29166667 | AB22: 0.83333333 | AC22: 1 | AD22: 0.375 | AE22: 0 | AF22: 0.083333333 | AG22: 0.16666667 | AH22: 0.29166667 | AI22: =IFERROR(MOD(AH22-AE22,1)-MOD(AG22-AF22,1),"") -> 0.20833333 | AJ22: OFF | AK22: OFF | AL22: OFF | AM22: OFF | AN22: =IFERROR(MOD(AM22-AJ22,1)-MOD(AL22-AK22,1),"") | AO22: =SUM(J22,O22,T22,Y22,AD22,AI22,AN22) -> 1.75
A23: SOA | B23: DENGUE ENGUENE ARLETTE PAULE | D23: ASSISTANCE | E23: FRE | F23: 0.54166667 | G23: 0.66666667 | H23: 0.70833333 | I23: 0.9375 | J23: =IFERROR(MOD(I23-F23,1)-MOD(H23-G23,1),"") -> 0.35416667 | K23: OFF | L23: OFF | M23: OFF | N23: OFF | O23: =IFERROR(MOD(N23-K23,1)-MOD(M23-L23,1),"") | P23: OFF | Q23: OFF | R23: OFF | S23: OFF | T23: =IFERROR(MOD(S23-P23,1)-MOD(R23-Q23,1),"") | U23: 0.29166667 | V23: 0.54166667 | W23: 0.625 | X23: 0.70833333 | Y23: =IFERROR(MOD(X23-U23,1)-MOD(W23-V23,1),"") -> 0.33333333 | Z23: 0.33333333 | AA23: 0.58333333 | AB23: 0.66666667 | AC23: 0.75 | AD23: =IFERROR(MOD(AC23-Z23,1)-MOD(AB23-AA23,1),"") -> 0.33333333 | AE23: 0.5 | AF23: 0.625 | AG23: 0.66666667 | AH23: 0.875 | AI23: =IFERROR(MOD(AH23-AE23,1)-MOD(AG23-AF23,1),"") -> 0.33333333 | AJ23: 0.4375 | AK23: 0.625 | AL23: 0.70833333 | AM23: 0.85416667 | AN23: =IFERROR(MOD(AM23-AJ23,1)-MOD(AL23-AK23,1),"") -> 0.33333333 | AO23: =SUM(J23,O23,T23,Y23,AD23,AI23,AN23) -> 1.6875
A24: PALAI | B24: TSEKAM LADORINE ARMELLE | D24: ASSISTANCE | E24: FRE | F24: 0.54166667 | G24: 0.66666667 | H24: 0.70833333 | I24: 0.91666667 | J24: =IFERROR(MOD(I24-F24,1)-MOD(H24-G24,1),"") -> 0.33333333 | K24: OFF | L24: OFF | M24: OFF | N24: OFF | O24: =IFERROR(MOD(N24-K24,1)-MOD(M24-L24,1),"") | P24: OFF | Q24: OFF | R24: OFF | S24: OFF | T24: =IFERROR(MOD(S24-P24,1)-MOD(R24-Q24,1),"") | U24: 0.29166667 | V24: 0.54166667 | W24: 0.625 | X24: 0.70833333 | Y24: =IFERROR(MOD(X24-U24,1)-MOD(W24-V24,1),"") -> 0.33333333 | Z24: 0.375 | AA24: 0.625 | AB24: 0.70833333 | AC24: 0.79166667 | AD24: =IFERROR(MOD(AC24-Z24,1)-MOD(AB24-AA24,1),"") -> 0.33333333 | AE24: 0.5 | AF24: 0.625 | AG24: 0.66666667 | AH24: 0.875 | AI24: =IFERROR(MOD(AH24-AE24,1)-MOD(AG24-AF24,1),"") -> 0.33333333 | AJ24: 0.52083333 | AK24: 0.66666667 | AL24: 0.70833333 | AM24: 0.89583333 | AN24: =IFERROR(MOD(AM24-AJ24,1)-MOD(AL24-AK24,1),"") -> 0.33333333 | AO24: =SUM(J24,O24,T24,Y24,AD24,AI24,AN24) -> 1.6666667
A25: ETUDI | B25: BADEFONA SOLANGE AUDREY GAELLE | D25: ASSISTANCE | E25: FRE | F25: 0.29166667 | G25: 0.41666667 | H25: 0.5 | I25: 0.70833333 | J25: =IFERROR(MOD(I25-F25,1)-MOD(H25-G25,1),"") -> 0.33333333 | K25: 0.33333333 | L25: 0.54166667 | M25: 0.625 | N25: 0.75 | O25: =IFERROR(MOD(N25-K25,1)-MOD(M25-L25,1),"") -> 0.33333333 | P25: 0.41666667 | Q25: 0.66666667 | R25: 0.75 | S25: 0.83333333 | T25: =IFERROR(MOD(S25-P25,1)-MOD(R25-Q25,1),"") -> 0.33333333 | U25: 0.54166667 | V25: 0.70833333 | W25: 0.75 | X25: 0.9375 | Y25: =IFERROR(MOD(X25-U25,1)-MOD(W25-V25,1),"") -> 0.35416667 | Z25: 0.54166667 | AA25: 0.75 | AB25: 0.79166667 | AC25: 0.91666667 | AD25: =IFERROR(MOD(AC25-Z25,1)-MOD(AB25-AA25,1),"") -> 0.33333333 | AE25: OFF | AF25: OFF | AG25: OFF | AH25: OFF | AI25: =IFERROR(MOD(AH25-AE25,1)-MOD(AG25-AF25,1),"") | AJ25: OFF | AK25: OFF | AL25: OFF | AM25: OFF | AN25: =IFERROR(MOD(AM25-AJ25,1)-MOD(AL25-AK25,1),"") | AO25: =SUM(J25,O25,T25,Y25,AD25,AI25,AN25) -> 1.6875
A26: ETOA | B26: PAKI OLIVE LAURETTE | D26: ASSISTANCE | E26: FRE | F26: 0.29166667 | G26: 0.5 | H26: 0.58333333 | I26: 0.70833333 | J26: =IFERROR(MOD(I26-F26,1)-MOD(H26-G26,1),"") -> 0.33333333 | K26: 0.3125 | L26: 0.41666667 | M26: 0.5 | N26: 0.72916667 | O26: =IFERROR(MOD(N26-K26,1)-MOD(M26-L26,1),"") -> 0.33333333 | P26: 0.3125 | Q26: 0.54166667 | R26: 0.625 | S26: 0.72916667 | T26: =IFERROR(MOD(S26-P26,1)-MOD(R26-Q26,1),"") -> 0.33333333 | U26: 0.375 | V26: 0.625 | W26: 0.70833333 | X26: 0.79166667 | Y26: =IFERROR(MOD(X26-U26,1)-MOD(W26-V26,1),"") -> 0.33333333 | Z26: 0.375 | AA26: 0.58333333 | AB26: 0.66666667 | AC26: 0.79166667 | AD26: =IFERROR(MOD(AC26-Z26,1)-MOD(AB26-AA26,1),"") -> 0.33333333 | AE26: OFF | AF26: OFF | AG26: OFF | AH26: OFF | AI26: =IFERROR(MOD(AH26-AE26,1)-MOD(AG26-AF26,1),"") | AJ26: OFF | AK26: OFF | AL26: OFF | AM26: OFF | AN26: =IFERROR(MOD(AM26-AJ26,1)-MOD(AL26-AK26,1),"") | AO26: =SUM(J26,O26,T26,Y26,AD26,AI26,AN26) -> 1.6666667
A27: SOA | B27: KIAMBA POUPIE GAELLE | C27: TT | D27: ASSISTANCE | E27: FRE | F27: 0.33333333 | G27: 0.54166667 | H27: 0.58333333 | I27: 0.66666667 | J27: =IFERROR(MOD(I27-F27,1)-MOD(H27-G27,1),"") -> 0.29166667 | K27: 0.33333333 | L27: 0.54166667 | M27: 0.58333333 | N27: 0.66666667 | O27: =IFERROR(MOD(N27-K27,1)-MOD(M27-L27,1),"") -> 0.29166667 | P27: 0.35416667 | Q27: 0.58333333 | R27: 0.625 | S27: 0.6875 | T27: =IFERROR(MOD(S27-P27,1)-MOD(R27-Q27,1),"") -> 0.29166667 | U27: OFF | V27: OFF | W27: OFF | X27: OFF | Y27: =IFERROR(MOD(X27-U27,1)-MOD(W27-V27,1),"") | Z27: OFF | AA27: OFF | AB27: OFF | AC27: OFF | AD27: =IFERROR(MOD(AC27-Z27,1)-MOD(AB27-AA27,1),"") | AE27: 0.35416667 | AF27: 0.58333333 | AG27: 0.625 | AH27: 0.6875 | AI27: =IFERROR(MOD(AH27-AE27,1)-MOD(AG27-AF27,1),"") -> 0.29166667 | AJ27: 0.35416667 | AK27: 0.54166667 | AL27: 0.58333333 | AM27: 0.6875 | AN27: =IFERROR(MOD(AM27-AJ27,1)-MOD(AL27-AK27,1),"") -> 0.29166667 | AO27: =SUM(J27,O27,T27,Y27,AD27,AI27,AN27) -> 1.4583333
A28: BIYEM | B28: TCHOUADJE SIWE CHRISTOPHE COLOMB | C28: S | D28: ASSISTANCE | E28: FRE | F28: 0.66666667 | I28: 0.9375 | J28: =IFERROR(MOD(I28-F28,1)-MOD(H28-G28,1),"") -> 0.27083333 | K28: 0.66666667 | N28: 0.9375 | O28: =IFERROR(MOD(N28-K28,1)-MOD(M28-L28,1),"") -> 0.27083333 | P28: 0.66666667 | S28: 0.9375 | T28: =IFERROR(MOD(S28-P28,1)-MOD(R28-Q28,1),"") -> 0.27083333 | U28: OFF | V28: OFF | W28: OFF | X28: OFF | Y28: =IFERROR(MOD(X28-U28,1)-MOD(W28-V28,1),"") | Z28: OFF | AA28: OFF | AB28: OFF | AC28: OFF | AD28: =IFERROR(MOD(AC28-Z28,1)-MOD(AB28-AA28,1),"") | AE28: 0.66666667 | AH28: 0.9375 | AI28: =IFERROR(MOD(AH28-AE28,1)-MOD(AG28-AF28,1),"") -> 0.27083333 | AJ28: 0.66666667 | AM28: 0.9375 | AN28: =IFERROR(MOD(AM28-AJ28,1)-MOD(AL28-AK28,1),"") -> 0.27083333 | AO28: =SUM(J28,O28,T28,Y28,AD28,AI28,AN28) -> 1.3541667
B29: BANENLA CLAUDINE | D29: ASSISTANCE | E29: ENG | F29: 0.29166667 | G29: 0.54166667 | H29: 0.625 | I29: 0.70833333 | J29: =IFERROR(MOD(I29-F29,1)-MOD(H29-G29,1),"") -> 0.33333333 | K29: 0.29166667 | L29: 0.54166667 | M29: 0.58333333 | N29: 0.66666667 | O29: =IFERROR(MOD(N29-K29,1)-MOD(M29-L29,1),"") -> 0.33333333 | P29: 0.5 | Q29: 0.625 | R29: 0.66666667 | S29: 0.875 | T29: =IFERROR(MOD(S29-P29,1)-MOD(R29-Q29,1),"") -> 0.33333333 | U29: 0.54166667 | V29: 0.66666667 | W29: 0.70833333 | X29: 0.91666667 | Y29: =IFERROR(MOD(X29-U29,1)-MOD(W29-V29,1),"") -> 0.33333333 | Z29: 0.54166667 | AA29: 0.625 | AB29: 0.66666667 | AC29: 0.91666667 | AD29: =IFERROR(MOD(AC29-Z29,1)-MOD(AB29-AA29,1),"") -> 0.33333333 | AE29: OFF | AF29: OFF | AG29: OFF | AH29: OFF | AI29: =IFERROR(MOD(AH29-AE29,1)-MOD(AG29-AF29,1),"") | AJ29: OFF | AK29: OFF | AL29: OFF | AM29: OFF | AN29: =IFERROR(MOD(AM29-AJ29,1)-MOD(AL29-AK29,1),"") | AO29: =SUM(J29,O29,T29,Y29,AD29,AI29,AN29) -> 1.6666667
B30: MAMAH FOTSING SYNTIA | D30: AUDACITY | E30: FRE | F30: 0.5 | G30: 0.625 | H30: 0.66666667 | I30: 0.875 | J30: =IFERROR(MOD(I30-F30,1)-MOD(H30-G30,1),"") -> 0.33333333 | K30: 0.41666667 | L30: 0.625 | M30: 0.70833333 | N30: 0.83333333 | O30: =IFERROR(MOD(N30-K30,1)-MOD(M30-L30,1),"") -> 0.33333333 | P30: 0.52083333 | Q30: 0.75 | R30: 0.79166667 | S30: 0.89583333 | T30: =IFERROR(MOD(S30-P30,1)-MOD(R30-Q30,1),"") -> 0.33333333 | U30: OFF | V30: OFF | W30: OFF | X30: OFF | Y30: =IFERROR(MOD(X30-U30,1)-MOD(W30-V30,1),"") | Z30: OFF | AA30: OFF | AB30: OFF | AC30: OFF | AD30: =IFERROR(MOD(AC30-Z30,1)-MOD(AB30-AA30,1),"") | AE30: 0.29166667 | AF30: 0.54166667 | AG30: 0.625 | AH30: 0.70833333 | AI30: =IFERROR(MOD(AH30-AE30,1)-MOD(AG30-AF30,1),"") -> 0.33333333 | AJ30: 0.29166667 | AK30: 0.54166667 | AL30: 0.625 | AM30: 0.70833333 | AN30: =IFERROR(MOD(AM30-AJ30,1)-MOD(AL30-AK30,1),"") -> 0.33333333 | AO30: =SUM(J30,O30,T30,Y30,AD30,AI30,AN30) -> 1.6666667
A31: SOA | B31: LANTOUM MOUSIMA DANIEL JUNIOR | D31: AUDACITY | E31: FRE | F31: 0.83333333 | I31: 1 | J31: =IFERROR(MOD(I31-F31,1)-MOD(H31-G31,1),"") -> 0.16666667 | K31: 0 | L31: 0.125 | M31: 0.20833333 | N31: 0.29166667 | O31: =IFERROR(MOD(N31-K31,1)-MOD(M31-L31,1),"") -> 0.20833333 | P31: OFF | Q31: OFF | R31: OFF | S31: OFF | T31: =IFERROR(MOD(S31-P31,1)-MOD(R31-Q31,1),"") | U31: 0.27083333 | V31: 0.41666667 | W31: 0.5 | X31: 0.6875 | Y31: =IFERROR(MOD(X31-U31,1)-MOD(W31-V31,1),"") -> 0.33333333 | Z31: 0.27083333 | AA31: 0.41666667 | AB31: 0.5 | AC31: 0.6875 | AD31: =IFERROR(MOD(AC31-Z31,1)-MOD(AB31-AA31,1),"") -> 0.33333333 | AE31: 0.5625 | AF31: 0.66666667 | AG31: 0.70833333 | AH31: 0.9375 | AI31: =IFERROR(MOD(AH31-AE31,1)-MOD(AG31-AF31,1),"") -> 0.33333333 | AJ31: 0.5625 | AK31: 0.75 | AL31: 0.79166667 | AM31: 0.9375 | AN31: =IFERROR(MOD(AM31-AJ31,1)-MOD(AL31-AK31,1),"") -> 0.33333333 | AO31: =SUM(J31,O31,T31,Y31,AD31,AI31,AN31) -> 1.7083333
A32: OKOLA | B32: KOUMBA EMILIENNE FRANCE LAETITIA | D32: AUDACITY | E32: FRE | F32: 0.54166667 | G32: 0.66666667 | H32: 0.70833333 | I32: 0.9375 | J32: =IFERROR(MOD(I32-F32,1)-MOD(H32-G32,1),"") -> 0.35416667 | K32: OFF | L32: OFF | M32: OFF | N32: OFF | O32: =IFERROR(MOD(N32-K32,1)-MOD(M32-L32,1),"") | P32: OFF | Q32: OFF | R32: OFF | S32: OFF | T32: =IFERROR(MOD(S32-P32,1)-MOD(R32-Q32,1),"") | U32: 0.29166667 | V32: 0.54166667 | W32: 0.625 | X32: 0.70833333 | Y32: =IFERROR(MOD(X32-U32,1)-MOD(W32-V32,1),"") -> 0.33333333 | Z32: 0.41666667 | AA32: 0.66666667 | AB32: 0.75 | AC32: 0.83333333 | AD32: =IFERROR(MOD(AC32-Z32,1)-MOD(AB32-AA32,1),"") -> 0.33333333 | AE32: 0.4375 | AF32: 0.58333333 | AG32: 0.66666667 | AH32: 0.85416667 | AI32: =IFERROR(MOD(AH32-AE32,1)-MOD(AG32-AF32,1),"") -> 0.33333333 | AJ32: 0.52083333 | AK32: 0.66666667 | AL32: 0.70833333 | AM32: 0.89583333 | AN32: =IFERROR(MOD(AM32-AJ32,1)-MOD(AL32-AK32,1),"") -> 0.33333333 | AO32: =SUM(J32,O32,T32,Y32,AD32,AI32,AN32) -> 1.6875
A33: SOA | B33: APKEH CARINE LAURICE | D33: AUDACITY | E33: FRE | F33: 0.5625 | G33: 0.79166667 | H33: 0.83333333 | I33: 0.9375 | J33: =IFERROR(MOD(I33-F33,1)-MOD(H33-G33,1),"") -> 0.33333333 | K33: OFF | L33: OFF | M33: OFF | N33: OFF | O33: =IFERROR(MOD(N33-K33,1)-MOD(M33-L33,1),"") | P33: OFF | Q33: OFF | R33: OFF | S33: OFF | T33: =IFERROR(MOD(S33-P33,1)-MOD(R33-Q33,1),"") | U33: 0.33333333 | V33: 0.58333333 | W33: 0.66666667 | X33: 0.75 | Y33: =IFERROR(MOD(X33-U33,1)-MOD(W33-V33,1),"") -> 0.33333333 | Z33: 0.3125 | AA33: 0.54166667 | AB33: 0.625 | AC33: 0.72916667 | AD33: =IFERROR(MOD(AC33-Z33,1)-MOD(AB33-AA33,1),"") -> 0.33333333 | AE33: 0.5 | AF33: 0.625 | AG33: 0.66666667 | AH33: 0.875 | AI33: =IFERROR(MOD(AH33-AE33,1)-MOD(AG33-AF33,1),"") -> 0.33333333 | AJ33: 0.39583333 | AK33: 0.625 | AL33: 0.70833333 | AM33: 0.8125 | AN33: =IFERROR(MOD(AM33-AJ33,1)-MOD(AL33-AK33,1),"") -> 0.33333333 | AO33: =SUM(J33,O33,T33,Y33,AD33,AI33,AN33) -> 1.6666667
A34: OLEMB | B34: NKOUMOU ANYOUZOA MYRIAM | D34: AUDACITY | E34: FRE | F34: 0.29166667 | G34: 0.54166667 | H34: 0.625 | I34: 0.70833333 | J34: =IFERROR(MOD(I34-F34,1)-MOD(H34-G34,1),"") -> 0.33333333 | K34: 0.29166667 | L34: 0.54166667 | M34: 0.625 | N34: 0.70833333 | O34: =IFERROR(MOD(N34-K34,1)-MOD(M34-L34,1),"") -> 0.33333333 | P34: 0.39583333 | Q34: 0.625 | R34: 0.70833333 | S34: 0.8125 | T34: =IFERROR(MOD(S34-P34,1)-MOD(R34-Q34,1),"") -> 0.33333333 | U34: 0.5 | V34: 0.66666667 | W34: 0.70833333 | X34: 0.875 | Y34: =IFERROR(MOD(X34-U34,1)-MOD(W34-V34,1),"") -> 0.33333333 | Z34: 0.45833333 | AA34: 0.70833333 | AB34: 0.75 | AC34: 0.83333333 | AD34: =IFERROR(MOD(AC34-Z34,1)-MOD(AB34-AA34,1),"") -> 0.33333333 | AE34: OFF | AF34: OFF | AG34: OFF | AH34: OFF | AI34: =IFERROR(MOD(AH34-AE34,1)-MOD(AG34-AF34,1),"") | AJ34: OFF | AK34: OFF | AL34: OFF | AM34: OFF | AN34: =IFERROR(MOD(AM34-AJ34,1)-MOD(AL34-AK34,1),"") | AO34: =SUM(J34,O34,T34,Y34,AD34,AI34,AN34) -> 1.6666667
A35: NKOLF | B35: ALIMA Marie Thérèse | D35: AUDACITY | E35: FRE | F35: 0.29166667 | G35: 0.5 | H35: 0.58333333 | I35: 0.70833333 | J35: =IFERROR(MOD(I35-F35,1)-MOD(H35-G35,1),"") -> 0.33333333 | K35: 0.3125 | L35: 0.41666667 | M35: 0.5 | N35: 0.72916667 | O35: =IFERROR(MOD(N35-K35,1)-MOD(M35-L35,1),"") -> 0.33333333 | P35: 0.3125 | Q35: 0.54166667 | R35: 0.625 | S35: 0.72916667 | T35: =IFERROR(MOD(S35-P35,1)-MOD(R35-Q35,1),"") -> 0.33333333 | U35: 0.5 | V35: 0.70833333 | W35: 0.75 | X35: 0.875 | Y35: =IFERROR(MOD(X35-U35,1)-MOD(W35-V35,1),"") -> 0.33333333 | Z35: 0.54166667 | AA35: 0.75 | AB35: 0.79166667 | AC35: 0.9375 | AD35: =IFERROR(MOD(AC35-Z35,1)-MOD(AB35-AA35,1),"") -> 0.35416667 | AE35: OFF | AF35: OFF | AG35: OFF | AH35: OFF | AI35: =IFERROR(MOD(AH35-AE35,1)-MOD(AG35-AF35,1),"") | AJ35: OFF | AK35: OFF | AL35: OFF | AM35: OFF | AN35: =IFERROR(MOD(AM35-AJ35,1)-MOD(AL35-AK35,1),"") | AO35: =SUM(J35,O35,T35,Y35,AD35,AI35,AN35) -> 1.6875
A36: FEBE | B36: SIDJE MBOUGUENG STEPHANIE | D36: AUDACITY | E36: FRE | F36: 0.41666667 | G36: 0.58333333 | H36: 0.66666667 | I36: 0.83333333 | J36: =IFERROR(MOD(I36-F36,1)-MOD(H36-G36,1),"") -> 0.33333333 | K36: 0.39583333 | L36: 0.58333333 | M36: 0.66666667 | N36: 0.8125 | O36: =IFERROR(MOD(N36-K36,1)-MOD(M36-L36,1),"") -> 0.33333333 | P36: OFF | Q36: OFF | R36: OFF | S36: OFF | T36: =IFERROR(MOD(S36-P36,1)-MOD(R36-Q36,1),"") | U36: OFF | V36: OFF | W36: OFF | X36: OFF | Y36: =IFERROR(MOD(X36-U36,1)-MOD(W36-V36,1),"") | Z36: 0.29166667 | AA36: 0.54166667 | AB36: 0.625 | AC36: 0.70833333 | AD36: =IFERROR(MOD(AC36-Z36,1)-MOD(AB36-AA36,1),"") -> 0.33333333 | AE36: 0.29166667 | AF36: 0.54166667 | AG36: 0.625 | AH36: 0.70833333 | AI36: =IFERROR(MOD(AH36-AE36,1)-MOD(AG36-AF36,1),"") -> 0.33333333 | AJ36: 0.3125 | AK36: 0.54166667 | AL36: 0.625 | AM36: 0.72916667 | AN36: =IFERROR(MOD(AM36-AJ36,1)-MOD(AL36-AK36,1),"") -> 0.33333333 | AO36: =SUM(J36,O36,T36,Y36,AD36,AI36,AN36) -> 1.6666667
A37: NKOMK | B37: MOUNG ESSOMBE CAROLE DESIREE | D37: AUDACITY | E37: FRE | F37: 0.29166667 | G37: 0.54166667 | H37: 0.625 | I37: 0.70833333 | J37: =IFERROR(MOD(I37-F37,1)-MOD(H37-G37,1),"") -> 0.33333333 | K37: 0.41666667 | L37: 0.58333333 | M37: 0.66666667 | N37: 0.83333333 | O37: =IFERROR(MOD(N37-K37,1)-MOD(M37-L37,1),"") -> 0.33333333 | P37: 0.41666667 | Q37: 0.66666667 | R37: 0.75 | S37: 0.83333333 | T37: =IFERROR(MOD(S37-P37,1)-MOD(R37-Q37,1),"") -> 0.33333333 | U37: 0.54166667 | V37: 0.70833333 | W37: 0.75 | X37: 0.9375 | Y37: =IFERROR(MOD(X37-U37,1)-MOD(W37-V37,1),"") -> 0.35416667 | Z37: OFF | AA37: OFF | AB37: OFF | AC37: OFF | AD37: =IFERROR(MOD(AC37-Z37,1)-MOD(AB37-AA37,1),"") | AE37: 0.29166667 | AF37: 0.54166667 | AG37: 0.625 | AH37: 0.70833333 | AI37: =IFERROR(MOD(AH37-AE37,1)-MOD(AG37-AF37,1),"") -> 0.33333333 | AJ37: OFF | AK37: OFF | AL37: OFF | AM37: OFF | AN37: =IFERROR(MOD(AM37-AJ37,1)-MOD(AL37-AK37,1),"") | AO37: =SUM(J37,O37,T37,Y37,AD37,AI37,AN37) -> 1.6875
A38: SOA | B38: MESSINA REGIS ALEXANDRA | C38: BU | D38: AUDACITY | E38: BU | J38: =IFERROR(MOD(I38-F38,1)-MOD(H38-G38,1),"") -> 0 | O38: =IFERROR(MOD(N38-K38,1)-MOD(M38-L38,1),"") -> 0 | T38: =IFERROR(MOD(S38-P38,1)-MOD(R38-Q38,1),"") -> 0 | Y38: =IFERROR(MOD(X38-U38,1)-MOD(W38-V38,1),"") -> 0 | AD38: =IFERROR(MOD(AC38-Z38,1)-MOD(AB38-AA38,1),"") -> 0 | AI38: =IFERROR(MOD(AH38-AE38,1)-MOD(AG38-AF38,1),"") -> 0 | AN38: =IFERROR(MOD(AM38-AJ38,1)-MOD(AL38-AK38,1),"") -> 0 | AO38: =SUM(J38,O38,T38,Y38,AD38,AI38,AN38) -> 0
A39: PALAI | B39: NGNIGNIPUTYA ALICE | C39: TT | D39: AUDACITY | E39: FRE | F39: 0.375 | G39: 0.58333333 | H39: 0.66666667 | I39: 0.70833333 | J39: =IFERROR(MOD(I39-F39,1)-MOD(H39-G39,1),"") -> 0.25 | K39: 0.35416667 | L39: 0.54166667 | M39: 0.58333333 | N39: 0.6875 | O39: =IFERROR(MOD(N39-K39,1)-MOD(M39-L39,1),"") -> 0.29166667 | P39: 0.35416667 | Q39: 0.58333333 | R39: 0.625 | S39: 0.6875 | T39: =IFERROR(MOD(S39-P39,1)-MOD(R39-Q39,1),"") -> 0.29166667 | U39: OFF | V39: OFF | W39: OFF | X39: OFF | Y39: =IFERROR(MOD(X39-U39,1)-MOD(W39-V39,1),"") | Z39: OFF | AA39: OFF | AB39: OFF | AC39: OFF | AD39: =IFERROR(MOD(AC39-Z39,1)-MOD(AB39-AA39,1),"") | AE39: 0.35416667 | AF39: 0.58333333 | AG39: 0.625 | AH39: 0.6875 | AI39: =IFERROR(MOD(AH39-AE39,1)-MOD(AG39-AF39,1),"") -> 0.29166667 | AJ39: 0.35416667 | AK39: 0.54166667 | AL39: 0.58333333 | AM39: 0.6875 | AN39: =IFERROR(MOD(AM39-AJ39,1)-MOD(AL39-AK39,1),"") -> 0.29166667 | AO39: =SUM(J39,O39,T39,Y39,AD39,AI39,AN39) -> 1.4166667
A40: ETUDI | B40: ETOUNOU AMOUGOU SOPHIE DORETTE | C40: TT | D40: AUDACITY | E40: FRE | F40: 0.35416667 | G40: 0.58333333 | H40: 0.625 | I40: 0.6875 | J40: =IFERROR(MOD(I40-F40,1)-MOD(H40-G40,1),"") -> 0.29166667 | K40: OFF | L40: OFF | M40: OFF | N40: OFF | O40: =IFERROR(MOD(N40-K40,1)-MOD(M40-L40,1),"") | P40: OFF | Q40: OFF | R40: OFF | S40: OFF | T40: =IFERROR(MOD(S40-P40,1)-MOD(R40-Q40,1),"") | U40: 0.35416667 | V40: 0.58333333 | W40: 0.625 | X40: 0.6875 | Y40: =IFERROR(MOD(X40-U40,1)-MOD(W40-V40,1),"") -> 0.29166667 | Z40: 0.35416667 | AA40: 0.54166667 | AB40: 0.58333333 | AC40: 0.6875 | AD40: =IFERROR(MOD(AC40-Z40,1)-MOD(AB40-AA40,1),"") -> 0.29166667 | AE40: 0.35416667 | AF40: 0.54166667 | AG40: 0.58333333 | AH40: 0.6875 | AI40: =IFERROR(MOD(AH40-AE40,1)-MOD(AG40-AF40,1),"") -> 0.29166667 | AJ40: 0.35416667 | AK40: 0.54166667 | AL40: 0.58333333 | AM40: 0.6875 | AN40: =IFERROR(MOD(AM40-AJ40,1)-MOD(AL40-AK40,1),"") -> 0.29166667 | AO40: =SUM(J40,O40,T40,Y40,AD40,AI40,AN40) -> 1.4583333
...

Sheet DA
B1: ="S"&_xlfn.ISOWEEKNUM(F1) -> S20 | F1: ='S&E'!H3 -> 46153 | K1: =F1+1 -> 46154 | P1: =K1+1 -> 46155 | U1: =P1+1 -> 46156 | Z1: =U1+1 -> 46157 | AE1: =Z1+1 -> 46158 | AJ1: =AE1+1 -> 46159 | AO1: 1.6666667 | AP1: =AO2/AO1 -> 29.275 | BT1: :
F2: Total jour | G2: =J2/"8:00:00" -> 21 | H2: =J2/$AO$2 -> 0.14346712 | I2: Heures | J2: =SUM(J4:J97) -> 7 | K2: Total jour | L2: =O2/"8:00:00" -> 21.5 | M2: =O2/$AO$2 -> 0.14688301 | N2: Heures | O2: =SUM(O4:O97) -> 7.1666667 | P2: Total jour | Q2: =T2/"8:00:00" -> 22.875 | R2: =T2/$AO$2 -> 0.15627669 | S2: Heures | T2: =SUM(T4:T97) -> 7.625 | U2: Total jour | V2: =Y2/"8:00:00" -> 20.875 | W2: =Y2/$AO$2 -> 0.14261315 | X2: Heures | Y2: =SUM(Y4:Y97) -> 6.9583333 | Z2: Total jour | AA2: =AD2/"8:00:00" -> 19.25 | AB2: =AD2/$AO$2 -> 0.13151153 | AC2: Heures | AD2: =SUM(AD4:AD97) -> 6.4166667 | AE2: Total jour | AF2: =AI2/"8:00:00" -> 20.5 | AG2: =AI2/$AO$2 -> 0.14005124 | AH2: Heures | AI2: =SUM(AI4:AI97) -> 6.8333333 | AJ2: Total jour | AK2: =AN2/"8:00:00" -> 20.375 | AL2: =AN2/$AO$2 -> 0.13919727 | AM2: Heures | AN2: =SUM(AN4:AN97) -> 6.7916667 | AO2: =SUM(AO4:AO96) -> 48.791667 | AP2: formation/réunion équipe | AQ2: HSUP | AT2: 0.33333333 | AW2: 1.6666667
B3: Agents | C3: comm1 | D3: Team | E3: COMP | F3: Début | G3: Pause | I3: Fin | J3: Total | K3: Début | L3: Pause | N3: Fin | O3: Total | P3: Début | Q3: Pause | S3: Fin | T3: Total | U3: Début | V3: Pause | X3: Fin | Y3: Total | Z3: Début | AA3: Pause | AC3: Fin | AD3: Total | AE3: Début | AF3: Pause | AH3: Fin | AI3: Total | AJ3: Début | AK3: Pause | AM3: Fin | AN3: Total | AO3: Total | AP3: formation/réunion équipe | AR3: Atelier/ réunion d'Equipe
B4: ABDOURAMAN ALI NGAMBO | D4: Digit- Engagement | E4: DA | F4: OFF | G4: OFF | H4: OFF | I4: OFF | J4: =IFERROR(MOD(I4-F4,1)-(H4-G4),"") | K4: 0.29166667 | L4: 0.54166667 | M4: 0.625 | N4: 0.70833333 | O4: =IFERROR(MOD(N4-K4,1)-(M4-L4),"") -> 0.33333333 | P4: 0.29166667 | Q4: 0.54166667 | R4: 0.58333333 | S4: 0.66666667 | T4: =IFERROR(MOD(S4-P4,1)-(R4-Q4),"") -> 0.33333333 | U4: 0.45833333 | V4: 0.66666667 | W4: 0.70833333 | X4: 0.83333333 | Y4: =IFERROR(MOD(X4-U4,1)-(W4-V4),"") -> 0.33333333 | Z4: 0.54166667 | AA4: 0.66666667 | AB4: 0.70833333 | AC4: 0.91666667 | AD4: =IFERROR(MOD(AC4-Z4,1)-(AB4-AA4),"") -> 0.33333333 | AE4: 0.54166667 | AF4: 0.66666667 | AG4: 0.70833333 | AH4: 0.91666667 | AI4: =IFERROR(MOD(AH4-AE4,1)-(AG4-AF4),"") -> 0.33333333 | AJ4: OFF | AK4: OFF | AL4: OFF | AM4: OFF | AN4: =IFERROR(MOD(AM4-AJ4,1)-(AL4-AK4),"") | AO4: =SUM(J4,O4,T4,Y4,AD4,AI4,AN4) -> 1.6666667
B5: MANIDAH TAPIEDA LORRAINE MERVEILLE | C5: 6 | D5: Digit- Engagement | E5: DA | F5: OFF | G5: OFF | H5: OFF | I5: OFF | J5: =IFERROR(MOD(I5-F5,1)-(H5-G5),"") | K5: OFF | L5: OFF | M5: OFF | N5: OFF | O5: =IFERROR(MOD(N5-K5,1)-(M5-L5),"") | P5: 0.29166667 | Q5: 0.5 | R5: 0.54166667 | S5: 0.66666667 | T5: =IFERROR(MOD(S5-P5,1)-(R5-Q5),"") -> 0.33333333 | U5: 0.29166667 | V5: 0.54166667 | W5: 0.58333333 | X5: 0.66666667 | Y5: =IFERROR(MOD(X5-U5,1)-(W5-V5),"") -> 0.33333333 | Z5: 0.45833333 | AA5: 0.66666667 | AB5: 0.70833333 | AC5: 0.83333333 | AD5: =IFERROR(MOD(AC5-Z5,1)-(AB5-AA5),"") -> 0.33333333 | AE5: 0.54166667 | AF5: 0.66666667 | AG5: 0.70833333 | AH5: 0.91666667 | AI5: =IFERROR(MOD(AH5-AE5,1)-(AG5-AF5),"") -> 0.33333333 | AJ5: 0.875 | AM5: 1 | AN5: =IFERROR(MOD(AM5-AJ5,1)-(AL5-AK5),"") -> 0.125 | AO5: =SUM(J5,O5,T5,Y5,AD5,AI5,AN5) -> 1.4583333 | AQ5: =IF(AO5>$AO$1, "Alerte Dépassement!!!","")
B6: ABOMO Madeleine | D6: Digit- Engagement | E6: DA | F6: 0.29166667 | G6: 0.5 | H6: 0.54166667 | I6: 0.66666667 | J6: =IFERROR(MOD(I6-F6,1)-(H6-G6),"") -> 0.33333333 | K6: 0.29166667 | L6: 0.5 | M6: 0.54166667 | N6: 0.66666667 | O6: =IFERROR(MOD(N6-K6,1)-(M6-L6),"") -> 0.33333333 | P6: 0.35416667 | Q6: 0.54166667 | R6: 0.58333333 | S6: 0.72916667 | T6: =IFERROR(MOD(S6-P6,1)-(R6-Q6),"") -> 0.33333333 | U6: 0.54166667 | V6: 0.66666667 | W6: 0.70833333 | X6: 0.91666667 | Y6: =IFERROR(MOD(X6-U6,1)-(W6-V6),"") -> 0.33333333 | Z6: 0.45833333 | AA6: 0.625 | AB6: 0.66666667 | AC6: 0.83333333 | AD6: =IFERROR(MOD(AC6-Z6,1)-(AB6-AA6),"") -> 0.33333333 | AE6: OFF | AF6: OFF | AG6: OFF | AH6: OFF | AI6: =IFERROR(MOD(AH6-AE6,1)-(AG6-AF6),"") | AJ6: OFF | AK6: OFF | AL6: OFF | AM6: OFF | AN6: =IFERROR(MOD(AM6-AJ6,1)-(AL6-AK6),"") | AO6: =SUM(J6,O6,T6,Y6,AD6,AI6,AN6) -> 1.6666667 | AQ6: =IF(AO6>$AO$1, "Alerte Dépassement!!!","")
B7: ZE DANY ROLAND | D7: Digit- Engagement | E7: DA | F7: 0 | G7: 0.083333333 | H7: 0.16666667 | I7: 0.29166667 | J7: =IFERROR(MOD(I7-F7,1)-(H7-G7),"") -> 0.20833333 | K7: 0.29166667 | L7: 0.5 | M7: 0.54166667 | N7: 0.66666667 | O7: =IFERROR(MOD(N7-K7,1)-(M7-L7),"") -> 0.33333333 | P7: 0.35416667 | Q7: 0.54166667 | R7: 0.58333333 | S7: 0.72916667 | T7: =IFERROR(MOD(S7-P7,1)-(R7-Q7),"") -> 0.33333333 | U7: 0.45833333 | V7: 0.70833333 | W7: 0.75 | X7: 0.83333333 | Y7: =IFERROR(MOD(X7-U7,1)-(W7-V7),"") -> 0.33333333 | Z7: 0.54166667 | AA7: 0.70833333 | AB7: 0.75 | AC7: 0.91666667 | AD7: =IFERROR(MOD(AC7-Z7,1)-(AB7-AA7),"") -> 0.33333333 | AE7: 0.875 | AH7: 1 | AI7: =IFERROR(MOD(AH7-AE7,1)-(AG7-AF7),"") -> 0.125 | AJ7: 0 | AK7: 0.083333333 | AL7: 0.16666667 | AM7: 0.29166667 | AN7: =IFERROR(MOD(AM7-AJ7,1)-(AL7-AK7),"") -> 0.20833333 | AO7: =SUM(J7,O7,T7,Y7,AD7,AI7,AN7) -> 1.875 | AQ7: =IF(AO7>$AO$1, "Alerte Dépassement!!!","") -> Alerte Dépassement!!!
B8: NYEHEG JOSE JAQUES | D8: Digit- Engagement | E8: DA | F8: 0.29166667 | G8: 0.5 | H8: 0.54166667 | I8: 0.66666667 | J8: =IFERROR(MOD(I8-F8,1)-(H8-G8),"") -> 0.33333333 | K8: 0.54166667 | L8: 0.66666667 | M8: 0.70833333 | N8: 0.91666667 | O8: =IFERROR(MOD(N8-K8,1)-(M8-L8),"") -> 0.33333333 | P8: 0.54166667 | Q8: 0.66666667 | R8: 0.70833333 | S8: 0.91666667 | T8: =IFERROR(MOD(S8-P8,1)-(R8-Q8),"") -> 0.33333333 | U8: 0.875 | X8: 1 | Y8: =IFERROR(MOD(X8-U8,1)-(W8-V8),"") -> 0.125 | Z8: 0 | AA8: 0.29166667 | AB8: 0.875 | AC8: 1 | AD8: 0.33333333 | AE8: 0 | AF8: 0.125 | AG8: 0.20833333 | AH8: 0.29166667 | AI8: =IFERROR(MOD(AH8-AE8,1)-(AG8-AF8),"") -> 0.20833333 | AJ8: OFF | AK8: OFF | AL8: OFF | AM8: OFF | AN8: =IFERROR(MOD(AM8-AJ8,1)-(AL8-AK8),"") | AO8: =SUM(J8,O8,T8,Y8,AD8,AI8,AN8) -> 1.6666667 | AQ8: =IF(AO8>$AO$1, "Alerte Dépassement!!!","")
B9: KAMNO TUENO FABIOLA BLANDINE | D9: Digit- Engagement | E9: DA | F9: 0.29166667 | G9: 0.54166667 | H9: 0.58333333 | I9: 0.66666667 | J9: =IFERROR(MOD(I9-F9,1)-(H9-G9),"") -> 0.33333333 | K9: 0.41666667 | L9: 0.58333333 | M9: 0.625 | N9: 0.79166667 | O9: =IFERROR(MOD(N9-K9,1)-(M9-L9),"") -> 0.33333333 | P9: 0.54166667 | Q9: 0.66666667 | R9: 0.70833333 | S9: 0.91666667 | T9: =IFERROR(MOD(S9-P9,1)-(R9-Q9),"") -> 0.33333333 | U9: 0.54166667 | V9: 0.66666667 | W9: 0.70833333 | X9: 0.91666667 | Y9: =IFERROR(MOD(X9-U9,1)-(W9-V9),"") -> 0.33333333 | Z9: OFF | AA9: OFF | AB9: OFF | AC9: OFF | AD9: =IFERROR(MOD(AC9-Z9,1)-(AB9-AA9),"") | AE9: OFF | AF9: OFF | AG9: OFF | AH9: OFF | AI9: =IFERROR(MOD(AH9-AE9,1)-(AG9-AF9),"") | AJ9: 0.29166667 | AK9: 0.54166667 | AL9: 0.58333333 | AM9: 0.66666667 | AN9: =IFERROR(MOD(AM9-AJ9,1)-(AL9-AK9),"") -> 0.33333333 | AO9: =SUM(J9,O9,T9,Y9,AD9,AI9,AN9) -> 1.6666667 | AQ9: =IF(AO9>$AO$1, "Alerte Dépassement!!!","")
B10: TOUPOUO CHAHAD | D10: Digit- Engagement | E10: DA | F10: 0 | G10: 0.083333333 | H10: 0.16666667 | I10: 0.29166667 | J10: =IFERROR(MOD(I10-F10,1)-(H10-G10),"") -> 0.20833333 | K10: 0.29166667 | L10: 0.54166667 | M10: 0.58333333 | N10: 0.66666667 | O10: =IFERROR(MOD(N10-K10,1)-(M10-L10),"") -> 0.33333333 | P10: 0.45833333 | Q10: 0.66666667 | R10: 0.70833333 | S10: 0.83333333 | T10: =IFERROR(MOD(S10-P10,1)-(R10-Q10),"") -> 0.33333333 | U10: 0.875 | X10: 1 | Y10: =IFERROR(MOD(X10-U10,1)-(W10-V10),"") -> 0.125 | Z10: 0 | AA10: 0.29166667 | AB10: 0.875 | AC10: 1 | AD10: 0.33333333 | AE10: 0 | AF10: 0.083333333 | AG10: 0.16666667 | AH10: 0.29166667 | AI10: =IFERROR(MOD(AH10-AE10,1)-(AG10-AF10),"") -> 0.20833333 | AJ10: OFF | AK10: OFF | AL10: OFF | AM10: OFF | AN10: =IFERROR(MOD(AM10-AJ10,1)-(AL10-AK10),"") | AO10: =SUM(J10,O10,T10,Y10,AD10,AI10,AN10) -> 1.5416667 | AQ10: =IF(AO10>$AO$1, "Alerte Dépassement!!!","")
B11: NGUEMESSI Manuella | D11: Digit- Engagement | E11: DA | F11: OFF | G11: OFF | H11: OFF | I11: OFF | J11: =IFERROR(MOD(I11-F11,1)-(H11-G11),"") | K11: OFF | L11: OFF | M11: OFF | N11: OFF | O11: =IFERROR(MOD(N11-K11,1)-(M11-L11),"") | P11: 0.29166667 | Q11: 0.54166667 | R11: 0.58333333 | S11: 0.66666667 | T11: =IFERROR(MOD(S11-P11,1)-(R11-Q11),"") -> 0.33333333 | U11: 0.29166667 | V11: 0.54166667 | W11: 0.58333333 | X11: 0.66666667 | Y11: =IFERROR(MOD(X11-U11,1)-(W11-V11),"") -> 0.33333333 | Z11: 0.29166667 | AA11: 0.54166667 | AB11: 0.58333333 | AC11: 0.66666667 | AD11: =IFERROR(MOD(AC11-Z11,1)-(AB11-AA11),"") -> 0.33333333 | AE11: 0.54166667 | AF11: 0.66666667 | AG11: 0.70833333 | AH11: 0.91666667 | AI11: =IFERROR(MOD(AH11-AE11,1)-(AG11-AF11),"") -> 0.33333333 | AJ11: 0.45833333 | AK11: 0.66666667 | AL11: 0.70833333 | AM11: 0.83333333 | AN11: =IFERROR(MOD(AM11-AJ11,1)-(AL11-AK11),"") -> 0.33333333 | AO11: =SUM(J11,O11,T11,Y11,AD11,AI11,AN11) -> 1.6666667 | AQ11: =IF(AO11>$AO$1, "Alerte Dépassement!!!","")
B12: KOMBOU Jose | D12: Digit- Engagement | E12: DA | F12: 0.875 | I12: 1 | J12: =IFERROR(MOD(I12-F12,1)-(H12-G12),"") -> 0.125 | K12: 0 | L12: 0.29166667 | M12: 0.875 | N12: 1 | O12: 0.33333333 | P12: 0 | Q12: 0.29166667 | R12: 0.875 | S12: 1 | T12: 0.33333333 | U12: 0 | V12: 0.16666667 | W12: 0.25 | X12: 0.29166667 | Y12: =IFERROR(MOD(X12-U12,1)-(W12-V12),"") -> 0.20833333 | Z12: OFF | AA12: OFF | AB12: OFF | AC12: OFF | AD12: =IFERROR(MOD(AC12-Z12,1)-(AB12-AA12),"") | AE12: 0.29166667 | AF12: 0.54166667 | AG12: 0.625 | AH12: 0.70833333 | AI12: =IFERROR(MOD(AH12-AE12,1)-(AG12-AF12),"") -> 0.33333333 | AJ12: 0.29166667 | AK12: 0.54166667 | AL12: 0.625 | AM12: 0.70833333 | AN12: =IFERROR(MOD(AM12-AJ12,1)-(AL12-AK12),"") -> 0.33333333 | AO12: =SUM(J12,O12,T12,Y12,AD12,AI12,AN12) -> 1.6666667 | AQ12: =IF(AO12>$AO$1, "Alerte Dépassement!!!","")
B13: MAMA EBODE BERNADETTE | D13: Digit- Engagement | E13: DA | F13: 0.41666667 | G13: 0.58333333 | H13: 0.625 | I13: 0.79166667 | J13: =IFERROR(MOD(I13-F13,1)-(H13-G13),"") -> 0.33333333 | K13: 0.54166667 | L13: 0.66666667 | M13: 0.70833333 | N13: 0.91666667 | O13: =IFERROR(MOD(N13-K13,1)-(M13-L13),"") -> 0.33333333 | P13: 0.54166667 | Q13: 0.66666667 | R13: 0.70833333 | S13: 0.91666667 | T13: =IFERROR(MOD(S13-P13,1)-(R13-Q13),"") -> 0.33333333 | U13: OFF | V13: OFF | W13: OFF | X13: OFF | Y13: =IFERROR(MOD(X13-U13,1)-(W13-V13),"") | Z13: OFF | AA13: OFF | AB13: OFF | AC13: OFF | AD13: =IFERROR(MOD(AC13-Z13,1)-(AB13-AA13),"") | AE13: 0.29166667 | AF13: 0.54166667 | AG13: 0.58333333 | AH13: 0.66666667 | AI13: =IFERROR(MOD(AH13-AE13,1)-(AG13-AF13),"") -> 0.33333333 | AJ13: 0.29166667 | AK13: 0.54166667 | AL13: 0.58333333 | AM13: 0.66666667 | AN13: =IFERROR(MOD(AM13-AJ13,1)-(AL13-AK13),"") -> 0.33333333 | AO13: =SUM(J13,O13,T13,Y13,AD13,AI13,AN13) -> 1.6666667 | AQ13: =IF(AO13>$AO$1, "Alerte Dépassement!!!","")
B14: MEBOUET KUATE ANNE PATRICIA | D14: Digit- Engagement | E14: DA | F14: 0.45833333 | G14: 0.625 | H14: 0.66666667 | I14: 0.83333333 | J14: =IFERROR(MOD(I14-F14,1)-(H14-G14),"") -> 0.33333333 | K14: 0.5 | L14: 0.625 | M14: 0.66666667 | N14: 0.875 | O14: =IFERROR(MOD(N14-K14,1)-(M14-L14),"") -> 0.33333333 | P14: 0.5 | Q14: 0.625 | R14: 0.66666667 | S14: 0.875 | T14: =IFERROR(MOD(S14-P14,1)-(R14-Q14),"") -> 0.33333333 | U14: OFF | V14: OFF | W14: OFF | X14: OFF | Y14: =IFERROR(MOD(X14-U14,1)-(W14-V14),"") | Z14: OFF | AA14: OFF | AB14: OFF | AC14: OFF | AD14: =IFERROR(MOD(AC14-Z14,1)-(AB14-AA14),"") | AE14: 0.29166667 | AF14: 0.54166667 | AG14: 0.625 | AH14: 0.70833333 | AI14: =IFERROR(MOD(AH14-AE14,1)-(AG14-AF14),"") -> 0.33333333 | AJ14: 0.29166667 | AK14: 0.5 | AL14: 0.54166667 | AM14: 0.66666667 | AN14: =IFERROR(MOD(AM14-AJ14,1)-(AL14-AK14),"") -> 0.33333333 | AO14: =SUM(J14,O14,T14,Y14,AD14,AI14,AN14) -> 1.6666667 | AQ14: =IF(AO14>$AO$1, "Alerte Dépassement!!!","")
B15: NGOUGOURE ALASA Aminatou | D15: Digit- Engagement | E15: DA | F15: 0 | G15: 0.29166667 | H15: 0.875 | I15: 1 | J15: 0.33333333 | K15: 0 | L15: 0.083333333 | M15: 0.16666667 | N15: 0.29166667 | O15: =IFERROR(MOD(N15-K15,1)-(M15-L15),"") -> 0.20833333 | P15: OFF | Q15: OFF | R15: OFF | S15: OFF | T15: =IFERROR(MOD(S15-P15,1)-(R15-Q15),"") | U15: OFF | V15: OFF | W15: OFF | X15: OFF | Y15: =IFERROR(MOD(X15-U15,1)-(W15-V15),"") | Z15: 0.875 | AC15: 1 | AD15: =IFERROR(MOD(AC15-Z15,1)-(AB15-AA15),"") -> 0.125 | AE15: 0 | AF15: 0.29166667 | AG15: 0.875 | AH15: 1 | AI15: 0.33333333 | AJ15: 0 | AK15: 0.29166667 | AL15: 0.875 | AM15: 1 | AN15: 0.33333333 | AO15: =SUM(J15,O15,T15,Y15,AD15,AI15,AN15) -> 1.3333333 | AQ15: =IF(AO15>$AO$1, "Alerte Dépassement!!!","")
B16: TEUKAM MBATKAM SYLVIE | D16: Digit- Engagement | E16: DA | F16: 0.45833333 | G16: 0.625 | H16: 0.66666667 | I16: 0.83333333 | J16: =IFERROR(MOD(I16-F16,1)-(H16-G16),"") -> 0.33333333 | K16: 0.45833333 | L16: 0.625 | M16: 0.66666667 | N16: 0.83333333 | O16: =IFERROR(MOD(N16-K16,1)-(M16-L16),"") -> 0.33333333 | P16: OFF | Q16: OFF | R16: OFF | S16: OFF | T16: =IFERROR(MOD(S16-P16,1)-(R16-Q16),"") | U16: OFF | V16: OFF | W16: OFF | X16: OFF | Y16: =IFERROR(MOD(X16-U16,1)-(W16-V16),"") | Z16: 0.375 | AA16: 0.625 | AB16: 0.66666667 | AC16: 0.75 | AD16: =IFERROR(MOD(AC16-Z16,1)-(AB16-AA16),"") -> 0.33333333 | AE16: 0.375 | AF16: 0.58333333 | AG16: 0.625 | AH16: 0.75 | AI16: =IFERROR(MOD(AH16-AE16,1)-(AG16-AF16),"") -> 0.33333333 | AJ16: 0.375 | AK16: 0.625 | AL16: 0.66666667 | AM16: 0.75 | AN16: =IFERROR(MOD(AM16-AJ16,1)-(AL16-AK16),"") -> 0.33333333 | AO16: =SUM(J16,O16,T16,Y16,AD16,AI16,AN16) -> 1.6666667
B17: GUEBU ESTHER CRISTELLE | C17: TAD | D17: Digit- Engagement | E17: DA | F17: 0.5 | G17: 0.58333333 | H17: 0.66666667 | I17: 0.91666667 | J17: =IFERROR(MOD(I17-F17,1)-(H17-G17),"") -> 0.33333333 | K17: OFF | L17: OFF | M17: OFF | N17: OFF | O17: =IFERROR(MOD(N17-K17,1)-(M17-L17),"") | P17: OFF | Q17: OFF | R17: OFF | S17: OFF | T17: =IFERROR(MOD(S17-P17,1)-(R17-Q17),"") | U17: 0.29166667 | V17: 0.375 | W17: 0.66666667 | X17: 0.91666667 | Y17: =IFERROR(MOD(X17-U17,1)-(W17-V17),"") -> 0.33333333 | Z17: 0.29166667 | AA17: 0.375 | AB17: 0.66666667 | AC17: 0.91666667 | AD17: =IFERROR(MOD(AC17-Z17,1)-(AB17-AA17),"") -> 0.33333333 | AE17: 0.41666667 | AF17: 0.66666667 | AG17: 0.70833333 | AH17: 0.79166667 | AI17: =IFERROR(MOD(AH17-AE17,1)-(AG17-AF17),"") -> 0.33333333 | AJ17: 0.41666667 | AK17: 0.5 | AL17: 0.66666667 | AM17: 0.91666667 | AN17: =IFERROR(MOD(AM17-AJ17,1)-(AL17-AK17),"") -> 0.33333333 | AO17: =SUM(J17,O17,T17,Y17,AD17,AI17,AN17) -> 1.6666667
B18: NNOMO Frida | D18: Digit- Engagement | E18: DA | F18: 0.5 | G18: 0.625 | H18: 0.66666667 | I18: 0.875 | J18: =IFERROR(MOD(I18-F18,1)-(H18-G18),"") -> 0.33333333 | K18: 0.54166667 | L18: 0.66666667 | M18: 0.70833333 | N18: 0.91666667 | O18: =IFERROR(MOD(N18-K18,1)-(M18-L18),"") -> 0.33333333 | P18: OFF | Q18: OFF | R18: OFF | S18: OFF | T18: =IFERROR(MOD(S18-P18,1)-(R18-Q18),"") | U18: OFF | V18: OFF | W18: OFF | X18: OFF | Y18: =IFERROR(MOD(X18-U18,1)-(W18-V18),"") | Z18: 0.29166667 | AA18: 0.54166667 | AB18: 0.58333333 | AC18: 0.66666667 | AD18: =IFERROR(MOD(AC18-Z18,1)-(AB18-AA18),"") -> 0.33333333 | AE18: 0.29166667 | AF18: 0.54166667 | AG18: 0.58333333 | AH18: 0.66666667 | AI18: =IFERROR(MOD(AH18-AE18,1)-(AG18-AF18),"") -> 0.33333333 | AJ18: 0.41666667 | AK18: 0.54166667 | AL18: 0.58333333 | AM18: 0.79166667 | AN18: =IFERROR(MOD(AM18-AJ18,1)-(AL18-AK18),"") -> 0.33333333 | AO18: =SUM(J18,O18,T18,Y18,AD18,AI18,AN18) -> 1.6666667
B19: TAINGO, Chinaze | D19: Digit- Engagement | E19: DA | F19: 0.29166667 | G19: 0.54166667 | H19: 0.58333333 | I19: 0.66666667 | J19: =IFERROR(MOD(I19-F19,1)-(H19-G19),"") -> 0.33333333 | K19: 0.29166667 | L19: 0.54166667 | M19: 0.58333333 | N19: 0.66666667 | O19: =IFERROR(MOD(N19-K19,1)-(M19-L19),"") -> 0.33333333 | P19: 0.29166667 | Q19: 0.54166667 | R19: 0.58333333 | S19: 0.66666667 | T19: =IFERROR(MOD(S19-P19,1)-(R19-Q19),"") -> 0.33333333 | U19: 0.45833333 | V19: 0.66666667 | W19: 0.70833333 | X19: 0.83333333 | Y19: =IFERROR(MOD(X19-U19,1)-(W19-V19),"") -> 0.33333333 | Z19: permission | AC19: permission | AD19: =IFERROR(MOD(AC19-Z19,1)-(AB19-AA19),"") | AE19: OFF | AF19: OFF | AG19: OFF | AH19: OFF | AI19: =IFERROR(MOD(AH19-AE19,1)-(AG19-AF19),"") | AJ19: OFF | AK19: OFF | AL19: OFF | AM19: OFF | AN19: =IFERROR(MOD(AM19-AJ19,1)-(AL19-AK19),"") | AO19: =SUM(J19,O19,T19,Y19,AD19,AI19,AN19) -> 1.3333333
B20: Germaine Merveille NGASSA MVOGO | D20: Digit-Impact | E20: DA | F20: OFF | G20: OFF | H20: OFF | I20: OFF | J20: =IFERROR(MOD(I20-F20,1)-(H20-G20),"") | K20: OFF | L20: OFF | M20: OFF | N20: OFF | O20: =IFERROR(MOD(N20-K20,1)-(M20-L20),"") | P20: 0.29166667 | Q20: 0.5 | R20: 0.54166667 | S20: 0.66666667 | T20: =IFERROR(MOD(S20-P20,1)-(R20-Q20),"") -> 0.33333333 | U20: 0.29166667 | V20: 0.5 | W20: 0.54166667 | X20: 0.66666667 | Y20: =IFERROR(MOD(X20-U20,1)-(W20-V20),"") -> 0.33333333 | Z20: 0.33333333 | AA20: 0.58333333 | AB20: 0.625 | AC20: 0.70833333 | AD20: =IFERROR(MOD(AC20-Z20,1)-(AB20-AA20),"") -> 0.33333333 | AE20: 0.5 | AF20: 0.625 | AG20: 0.66666667 | AH20: 0.875 | AI20: =IFERROR(MOD(AH20-AE20,1)-(AG20-AF20),"") -> 0.33333333 | AJ20: 0.5 | AK20: 0.625 | AL20: 0.66666667 | AM20: 0.875 | AN20: =IFERROR(MOD(AM20-AJ20,1)-(AL20-AK20),"") -> 0.33333333 | AO20: =SUM(J20,O20,T20,Y20,AD20,AI20,AN20) -> 1.6666667
B21: GUIADEM MURIELLE SONIA | D21: Digit-Impact | E21: DA | F21: HP | G21: HP | H21: HP | I21: HP | J21: =IFERROR(MOD(I21-F21,1)-(H21-G21),"") | K21: HP | L21: HP | M21: HP | N21: HP | O21: =IFERROR(MOD(N21-K21,1)-(M21-L21),"") | P21: HP | Q21: HP | R21: HP | S21: HP | T21: =IFERROR(MOD(S21-P21,1)-(R21-Q21),"") | U21: HP | V21: HP | W21: HP | X21: HP | Y21: =IFERROR(MOD(X21-U21,1)-(W21-V21),"") | Z21: HP | AA21: HP | AB21: HP | AC21: HP | AD21: =IFERROR(MOD(AC21-Z21,1)-(AB21-AA21),"") | AE21: HP | AF21: HP | AG21: HP | AH21: HP | AI21: =IFERROR(MOD(AH21-AE21,1)-(AG21-AF21),"") | AJ21: HP | AK21: HP | AL21: HP | AM21: HP | AN21: =IFERROR(MOD(AM21-AJ21,1)-(AL21-AK21),"") | AO21: =SUM(J21,O21,T21,Y21,AD21,AI21,AN21) -> 0 | AQ21: =IF(AO21>$AO$1, "Alerte Dépassement!!!","")
